Workbook
Name Alpha: 'Fixing Money'!#REF!
Name Beta: 'Fixing Money'!$B$9
Name Beta0_0: 'Fixing Money'!$B$18
Name Beta0_1: 'Fixing Money'!$C$18
Name Beta1: 'Fixing Money'!$B$12
Name Delta: 'Fixing Money'!$B$11
Name m_0: 'Fixing Money'!$B$17
Name m_1: 'Fixing Money'!$C$17
Name Mi: 'Fixing Money'!$B$13
Name Ni: 'Fixing Money'!$B$14
Name pbar_0: 'Fixing Money'!$B$22
Name pbar_1: 'Fixing Money'!$C$22
Name Psi: 'Fixing Money'!$B$10
Name Theta: 'Fixing Money'!$B$11
Name ybar0: 'Fixing Money'!$B$23
Name ybar1: 'Fixing Money'!$C$23
Name ypot_0: 'Fixing Money'!$B$19
Name ypot_1: 'Fixing Money'!$C$19
Name ypot0: 'Fixing Money'!$B$19
Name ypot1: 'Fixing Money'!$C$19

Sheet Fixing Money
A1: EXERCISE 2: Dynamic IS-LM model with a Recurring Productivity Shock: Fixing Money and Adjusting Interest Rates | T1: fixed ep
E2: Time | F2: p | G2: y | H2: yd | I2: yn | J2: Gap | K2: m | L2: i | M2: ∆p | N2: Real i | O2: ∆y | P2: epsilon | Q2: z | R2: Z | S2: ∆i | T2: epsilon
A3: Endogenous variables | B3: Change over time | E3: 0 | F3: =(Theta*Beta0_0)/Beta1+m_0-(Psi+Theta/Beta1)*ypot_0 -> 1 | G3: =ypot_0 -> 2000 | H3: =Beta0_0 -Beta1*(L3-M3) -> 2000 | I3: =ypot_0*R3 -> 2000 | J3: =LN(G3/I3) -> 0 | K3: =100 -> 100 | L3: =MAX(0,-1/Theta*(K3-F3-Psi*G3)) -> 2 | M3: =Mi*J3 -> 0 | N3: =L3-M3 -> 2 | O3: =Ni*(H3-G3) -> 1.3642421e-13 | P3: 0 | Q3: 0 | R3: 1 | S3: 0 | T3: 0
A4: p: Price level | B4: ∆p: Inflation | E4: 1 | F4: =F3+M3 -> 1 | G4: =G3+O3 -> 2000 | H4: =Beta0_0 -Beta1*(L4-M4) -> 2010 | I4: =ypot_0*R4 -> 2000 | J4: =LN(G4/I4) -> 2.220446e-16 | K4: =K3+0.1 -> 100.1 | L4: =MAX(0,-1/Theta*(K4-F4-Psi*G4)) -> 1.8 | M4: =Mi*LN(G4/(I4)) -> 2.220446e-17 | N4: =L4-M4 -> 1.8 | O4: =Ni*(H4-G4) -> 1 | P4: 0 | Q4: =$C$33*Q3+T4 -> 0 | R4: =EXP(Q4) -> 1 | S4: =L4-L3 -> -0.2 | T4: 0
A5: y: Output | B5: ∆y: Output growth | E5: 2 | F5: =F4+M4 -> 1 | G5: =G4+O4 -> 2001 | H5: =Beta0_0 -Beta1*(L5-M5) -> 2015.2115 | I5: =ypot_0*R5 -> 1918.1403 | J5: =LN(G5/I5) -> 0.042290921 | K5: =K4+0.1 -> 100.2 | L5: =MAX(0,-1/Theta*(K5-F5-Psi*G5)) -> 1.7 | M5: =Mi*LN(G5/(I5)) -> 0.0042290921 | N5: =L5-M5 -> 1.6957709 | O5: =Ni*(H5-G5) -> 1.4211455 | P5: =NORMINV(RAND(), 0, $C$34) -> -0.032427153 | Q5: =$C$33*Q4+T5 -> -0.041791046 | R5: =EXP(Q5) -> 0.95907016 | S5: =L5-L4 -> -0.1 | T5: -0.041791046
A6: yd: Aggregate demand | E6: 3 | F6: =F5+M5 -> 1.0042291 | G6: =G5+O5 -> 2002.4211 | H6: =Beta0_0 -Beta1*(L6-M6) -> 2017.6841 | I6: =ypot_0*R6 -> 1919.0104 | J6: =LN(G6/I6) -> 0.042547409 | K6: =K5+0.1 -> 100.3 | L6: =MAX(0,-1/Theta*(K6-F6-Psi*G6)) -> 1.6505727 | M6: =Mi*LN(G6/(I6)) -> 0.0042547409 | N6: =L6-M6 -> 1.646318 | O6: =Ni*(H6-G6) -> 1.5262955 | P6: =NORMINV(RAND(), 0, $C$34) -> 0.063067809 | Q6: =$C$33*Q5+T6 -> -0.041337568 | R6: =EXP(Q6) -> 0.95950518 | S6: =L6-L5 -> -0.04942727 | T6: -0.0037256268
A7: i: Nominal interest rate | E7: 4 | F7: =F6+M6 -> 1.0084838 | G7: =G6+O6 -> 2003.9474 | H7: =Beta0_0 -Beta1*(L7-M7) -> 2019.7615 | I7: =ypot_0*R7 -> 1869.5496 | J7: =LN(G7/I7) -> 0.069421429 | K7: =K6+0.1 -> 100.4 | L7: =MAX(0,-1/Theta*(K7-F7-Psi*G7)) -> 1.6117118 | M7: =Mi*LN(G7/(I7)) -> 0.0069421429 | N7: =L7-M7 -> 1.6047696 | O7: =Ni*(H7-G7) -> 1.5814078 | P7: =NORMINV(RAND(), 0, $C$34) -> 0.17506394 | Q7: =$C$33*Q6+T7 -> -0.067449654 | R7: =EXP(Q7) -> 0.93477478 | S7: =L7-L6 -> -0.038860968 | T7: -0.030245842
E8: 5 | F8: =F7+M7 -> 1.015426 | G8: =G7+O7 -> 2005.5288 | H8: =Beta0_0 -Beta1*(L8-M8) -> 2021.0485 | I8: =ypot_0*R8 -> 1913.313 | J8: =LN(G8/I8) -> 0.047071511 | K8: =K7+0.1 -> 100.5 | L8: =MAX(0,-1/Theta*(K8-F8-Psi*G8)) -> 1.5837368 | M8: =Mi*LN(G8/(I8)) -> 0.0047071511 | N8: =L8-M8 -> 1.5790297 | O8: =Ni*(H8-G8) -> 1.5519667 | P8: =NORMINV(RAND(), 0, $C$34) -> -0.015373145 | Q8: =$C$33*Q7+T8 -> -0.044310901 | R8: =EXP(Q8) -> 0.95665649 | S8: =L8-L7 -> -0.027974934 | T8: 0.016393788
A9: Parameters | E9: 6 | F9: =F8+M8 -> 1.0201331 | G9: =G8+O8 -> 2007.0808 | H9: =Beta0_0 -Beta1*(L9-M9) -> 2022.9775 | I9: =ypot_0*R9 -> 1854.6652 | J9: =LN(G9/I9) -> 0.078977163 | K9: =K8+0.1 -> 100.6 | L9: =MAX(0,-1/Theta*(K9-F9-Psi*G9)) -> 1.5483478 | M9: =Mi*LN(G9/(I9)) -> 0.0078977163 | N9: =L9-M9 -> 1.5404501 | O9: =Ni*(H9-G9) -> 1.589668 | P9: =NORMINV(RAND(), 0, $C$34) -> -0.039132545 | Q9: =$C$33*Q8+T9 -> -0.075443008 | R9: =EXP(Q9) -> 0.92733258 | S9: =L9-L8 -> -0.035389024 | T9: -0.035563197
A10: Psi | B10: 0.05 | E10: 7 | F10: =F9+M9 -> 1.0280308 | G10: =G9+O9 -> 2008.6705 | H10: =Beta0_0 -Beta1*(L10-M10) -> 2024.0329 | I10: =ypot_0*R10 -> 1934.3953 | J10: =LN(G10/I10) -> 0.03767826 | K10: =K9+0.1 -> 100.7 | L10: =MAX(0,-1/Theta*(K10-F10-Psi*G10)) -> 1.52311 | M10: =Mi*LN(G10/(I10)) -> 0.003767826 | N10: =L10-M10 -> 1.5193422 | O10: =Ni*(H10-G10) -> 1.5362406 | P10: =NORMINV(RAND(), 0, $C$34) -> -0.0063226409 | Q10: =$C$33*Q9+T10 -> -0.033352388 | R10: =EXP(Q10) -> 0.96719767 | S10: =L10-L9 -> -0.025237767 | T10: 0.034546319
A11: Theta | B11: 0.5 | E11: 8 | F11: =F10+M10 -> 1.0317987 | G11: =G10+O10 -> 2010.2067 | H11: =Beta0_0 -Beta1*(L11-M11) -> 2025.5912 | I11: =ypot_0*R11 -> 2090.29 | J11: =LN(G11/I11) -> -0.039065246 | K11: =K10+0.1 -> 100.8 | L11: =MAX(0,-1/Theta*(K11-F11-Psi*G11)) -> 1.4842697 | M11: =Mi*LN(G11/(I11)) -> -0.0039065246 | N11: =L11-M11 -> 1.4881763 | O11: =Ni*(H11-G11) -> 1.5384462 | P11: =NORMINV(RAND(), 0, $C$34) -> -0.022154893 | Q11: =$C$33*Q10+T11 -> 0.04415563 | R11: =EXP(Q11) -> 1.045145 | S11: =L11-L10 -> -0.038840289 | T11: 0.074172779
A12: Beta1 | B12: 50 | E12: 9 | F12: =F11+M11 -> 1.0278921 | G12: =G11+O11 -> 2011.7452 | H12: =Beta0_0 -Beta1*(L12-M12) -> 2028.1211 | I12: =ypot_0*R12 -> 2163.5871 | J12: =LN(G12/I12) -> -0.072764949 | K12: =K11+0.1 -> 100.9 | L12: =MAX(0,-1/Theta*(K12-F12-Psi*G12)) -> 1.4303013 | M12: =Mi*LN(G12/(I12)) -> -0.0072764949 | N12: =L12-M12 -> 1.4375778 | O12: =Ni*(H12-G12) -> 1.6375939 | P12: =NORMINV(RAND(), 0, $C$34) -> 0.058675604 | Q12: =$C$33*Q11+T12 -> 0.078620358 | R12: =EXP(Q12) -> 1.0817935 | S12: =L12-L11 -> -0.053968427 | T12: 0.038880291
A13: Mi | B13: 0.1 | E13: 10 | F13: =F12+M12 -> 1.0206156 | G13: =G12+O12 -> 2013.3828 | H13: =Beta0_0 -Beta1*(L13-M13) -> 2030.9429 | I13: =ypot_0*R13 -> 2046.5413 | J13: =LN(G13/I13) -> -0.016334934 | K13: =K12+0.1 -> 101 | L13: =MAX(0,-1/Theta*(K13-F13-Psi*G13)) -> 1.3795077 | M13: =Mi*LN(G13/(I13)) -> -0.0016334934 | N13: =L13-M13 -> 1.3811412 | O13: =Ni*(H13-G13) -> 1.7560175 | P13: =NORMINV(RAND(), 0, $C$34) -> 0.11716061 | Q13: =$C$33*Q12+T13 -> 0.023004028 | R13: =EXP(Q13) -> 1.0232707 | S13: =L13-L12 -> -0.050793602 | T13: -0.047754294
A14: Ni | B14: 0.1 | E14: 11 | F14: =F13+M13 -> 1.0189822 | G14: =G13+O13 -> 2015.1388 | H14: =Beta0_0 -Beta1*(L14-M14) -> 2032.6401 | I14: =ypot_0*R14 -> 1923.6786 | J14: =LN(G14/I14) -> 0.046448758 | K14: =K13+0.1 -> 101.1 | L14: =MAX(0,-1/Theta*(K14-F14-Psi*G14)) -> 1.3518425 | M14: =Mi*LN(G14/(I14)) -> 0.0046448758 | N14: =L14-M14 -> 1.3471976 | O14: =Ni*(H14-G14) -> 1.7501338 | P14: =NORMINV(RAND(), 0, $C$34) -> 0.040820445 | Q14: =$C$33*Q13+T14 -> -0.038907871 | R14: =EXP(Q14) -> 0.96183932 | S14: =L14-L13 -> -0.027665236 | T14: -0.059611496
E15: 12 | F15: =F14+M14 -> 1.023627 | G15: =G14+O14 -> 2016.8889 | H15: =Beta0_0 -Beta1*(L15-M15) -> 2033.7502 | I15: =ypot_0*R15 -> 1804.1132 | J15: =LN(G15/I15) -> 0.11148702 | K15: =K14+0.1 -> 101.2 | L15: =MAX(0,-1/Theta*(K15-F15-Psi*G15)) -> 1.3361456 | M15: =Mi*LN(G15/(I15)) -> 0.011148702 | N15: =L15-M15 -> 1.3249969 | O15: =Ni*(H15-G15) -> 1.6861239 | P15: =NORMINV(RAND(), 0, $C$34) -> 0.065941603 | Q15: =$C$33*Q14+T15 -> -0.10307802 | R15: =EXP(Q15) -> 0.90205659 | S15: =L15-L14 -> -0.01569687 | T15: -0.068060934
A16: Exogenous variables | B16: Initial value | C16: Final value | E16: 13 | F16: =F15+M15 -> 1.0347757 | G16: =G15+O15 -> 2018.575 | H16: =Beta0_0 -Beta1*(L16-M16) -> 2033.7361 | I16: =ypot_0*R16 -> 1983.0169 | J16: =LN(G16/I16) -> 0.017772455 | K16: =K15+0.1 -> 101.3 | L16: =MAX(0,-1/Theta*(K16-F16-Psi*G16)) -> 1.3270554 | M16: =Mi*LN(G16/(I16)) -> 0.0017772455 | N16: =L16-M16 -> 1.3252782 | O16: =Ni*(H16-G16) -> 1.5161053 | P16: =NORMINV(RAND(), 0, $C$34) -> -0.08553997 | Q16: =$C$33*Q15+T16 -> -0.0085277988 | R16: =EXP(Q16) -> 0.99150846 | S16: =L16-L15 -> -0.0090902071 | T16: 0.084242417
A17: m: Money | B17: 100 | C17: 100 | E17: 14 | F17: =F16+M16 -> 1.036553 | G17: =G16+O16 -> 2020.0911 | H17: =Beta0_0 -Beta1*(L17-M17) -> 2036.3993 | I17: =ypot_0*R17 -> 1824.081 | J17: =LN(G17/I17) -> 0.10206632 | K17: =K16+0.1 -> 101.4 | L17: =MAX(0,-1/Theta*(K17-F17-Psi*G17)) -> 1.2822204 | M17: =Mi*LN(G17/(I17)) -> 0.010206632 | N17: =L17-M17 -> 1.2720138 | O17: =Ni*(H17-G17) -> 1.6308166 | P17: =NORMINV(RAND(), 0, $C$34) -> -0.025298068 | Q17: =$C$33*Q16+T17 -> -0.092070867 | R17: =EXP(Q17) -> 0.91204051 | S17: =L17-L16 -> -0.044834984 | T17: -0.084395848
A18: Beta0: Government spending | B18: 2100 | C18: 2100 | E18: 15 | F18: =F17+M17 -> 1.0467596 | G18: =G17+O17 -> 2021.722 | H18: =Beta0_0 -Beta1*(L18-M18) -> 2037.284 | I18: =ypot_0*R18 -> 1803.9812 | J18: =LN(G18/I18) -> 0.11395361 | K18: =K17+0.1 -> 101.5 | L18: =MAX(0,-1/Theta*(K18-F18-Psi*G18)) -> 1.2657153 | M18: =Mi*LN(G18/(I18)) -> 0.011395361 | N18: =L18-M18 -> 1.25432 | O18: =Ni*(H18-G18) -> 1.556204 | P18: =NORMINV(RAND(), 0, $C$34) -> -0.011113111 | Q18: =$C$33*Q17+T18 -> -0.10315119 | R18: =EXP(Q18) -> 0.90199059 | S18: =L18-L17 -> -0.016505079 | T18: -0.020287407
A19: Ypot: Potential output | B19: 2000 | C19: 2000 | E19: 16 | F19: =F18+M18 -> 1.058155 | G19: =G18+O18 -> 2023.2782 | H19: =Beta0_0 -Beta1*(L19-M19) -> 2038.3627 | I19: =ypot_0*R19 -> 1805.6281 | J19: =LN(G19/I19) -> 0.11381053 | K19: =K18+0.1 -> 101.6 | L19: =MAX(0,-1/Theta*(K19-F19-Psi*G19)) -> 1.2441265 | M19: =Mi*LN(G19/(I19)) -> 0.011381053 | N19: =L19-M19 -> 1.2327454 | O19: =Ni*(H19-G19) -> 1.5084564 | P19: =NORMINV(RAND(), 0, $C$34) -> 0.060955149 | Q19: =$C$33*Q18+T19 -> -0.10223866 | R19: =EXP(Q19) -> 0.90281406 | S19: =L19-L18 -> -0.021588882 | T19: -0.0094025934
E20: 17 | F20: =F19+M19 -> 1.069536 | G20: =G19+O19 -> 2024.7866 | H20: =Beta0_0 -Beta1*(L20-M20) -> 2039.6872 | I20: =ypot_0*R20 -> 1805.2309 | J20: =LN(G20/I20) -> 0.1147758 | K20: =K19+0.1 -> 101.7 | L20: =MAX(0,-1/Theta*(K20-F20-Psi*G20)) -> 1.2177342 | M20: =Mi*LN(G20/(I20)) -> 0.01147758 | N20: =L20-M20 -> 1.2062566 | O20: =Ni*(H20-G20) -> 1.4900547 | P20: =NORMINV(RAND(), 0, $C$34) -> -0.034670115 | Q20: =$C$33*Q19+T20 -> -0.10245866 | R20: =EXP(Q20) -> 0.90261546 | S20: =L20-L19 -> -0.02639225 | T20: -0.010443865
A21: Steady State | B21: Initial SS | C21: Final SS | E21: 18 | F21: =F20+M20 -> 1.0810136 | G21: =G20+O20 -> 2026.2767 | H21: =Beta0_0 -Beta1*(L21-M21) -> 2040.7731 | I21: =ypot_0*R21 -> 1924.438 | J21: =LN(G21/I21) -> 0.051565995 | K21: =K20+0.1 -> 101.8 | L21: =MAX(0,-1/Theta*(K21-F21-Psi*G21)) -> 1.1896948 | M21: =Mi*LN(G21/(I21)) -> 0.0051565995 | N21: =L21-M21 -> 1.1845382 | O21: =Ni*(H21-G21) -> 1.4496412 | P21: =NORMINV(RAND(), 0, $C$34) -> -0.010745592 | Q21: =$C$33*Q20+T21 -> -0.038513216 | R21: =EXP(Q21) -> 0.96221899 | S21: =L21-L20 -> -0.028039372 | T21: 0.053699578
A22: Steady state for p | B22: =(Theta*Beta0_0)/Beta1+m_0-(Psi+Theta/Beta1)*ybar0 -> 1 | C22: =(Theta*Beta0_1)/Beta1+m_1-(Psi+Theta/Beta1)*ybar1 -> 1 | E22: 19 | F22: =F21+M21 -> 1.0861702 | G22: =G21+O21 -> 2027.7263 | H22: =Beta0_0 -Beta1*(L22-M22) -> 2042.9612 | I22: =ypot_0*R22 -> 1944.4137 | J22: =LN(G22/I22) -> 0.041954638 | K22: =K21+0.1 -> 101.9 | L22: =MAX(0,-1/Theta*(K22-F22-Psi*G22)) -> 1.1449722 | M22: =Mi*LN(G22/(I22)) -> 0.0041954638 | N22: =L22-M22 -> 1.1407767 | O22: =Ni*(H22-G22) -> 1.5234848 | P22: =NORMINV(RAND(), 0, $C$34) -> -0.03327487 | Q22: =$C$33*Q21+T22 -> -0.028186694 | R22: =EXP(Q22) -> 0.97220684 | S22: =L22-L21 -> -0.044722685 | T22: 0.0064752007
A23: Steady state for y | B23: =ypot0 -> 2000 | C23: =ypot1 -> 2000 | E23: 20 | F23: =F22+M22 -> 1.0903657 | G23: =G22+O22 -> 2029.2498 | H23: =Beta0_0 -Beta1*(L23-M23) -> 2044.6915 | I23: =ypot_0*R23 -> 2038.556 | J23: =LN(G23/I23) -> -0.0045755328 | K23: =K22+0.1 -> 102 | L23: =MAX(0,-1/Theta*(K23-F23-Psi*G23)) -> 1.1057116 | M23: =Mi*LN(G23/(I23)) -> -0.00045755328 | N23: =L23-M23 -> 1.1061691 | O23: =Ni*(H23-G23) -> 1.5441742 | P23: =NORMINV(RAND(), 0, $C$34) -> 0.04242673 | Q23: =$C$33*Q22+T23 -> 0.019094521 | R23: =EXP(Q23) -> 1.019278 | S23: =L23-L22 -> -0.039260593 | T23: 0.044462546
E24: 21 | F24: =F23+M23 -> 1.0899081 | G24: =G23+O23 -> 2030.794 | H24: =Beta0_0 -Beta1*(L24-M24) -> 2047.3136 | I24: =ypot_0*R24 -> 1922.3896 | J24: =LN(G24/I24) -> 0.054857841 | K24: =K23+0.1 -> 102.1 | L24: =MAX(0,-1/Theta*(K24-F24-Psi*G24)) -> 1.0592139 | M24: =Mi*LN(G24/(I24)) -> 0.0054857841 | N24: =L24-M24 -> 1.0537281 | O24: =Ni*(H24-G24) -> 1.6519619 | P24: =NORMINV(RAND(), 0, $C$34) -> 0.097560915 | Q24: =$C$33*Q23+T24 -> -0.039578184 | R24: =EXP(Q24) -> 0.9611948 | S24: =L24-L23 -> -0.046497687 | T24: -0.056763253
A25: Eigenvalues | B25: Real | C25: Imaginary | E25: 22 | F25: =F24+M24 -> 1.0953939 | G25: =G24+O24 -> 2032.4459 | H25: =Beta0_0 -Beta1*(L25-M25) -> 2048.6311 | I25: =ypot_0*R25 -> 1876.1176 | J25: =LN(G25/I25) -> 0.080035423 | K25: =K24+0.1 -> 102.2 | L25: =MAX(0,-1/Theta*(K25-F25-Psi*G25)) -> 1.0353816 | M25: =Mi*LN(G25/(I25)) -> 0.0080035423 | N25: =L25-M25 -> 1.0273781 | O25: =Ni*(H25-G25) -> 1.6185157 | P25: =NORMINV(RAND(), 0, $C$34) -> -0.043523728 | Q25: =$C$33*Q24+T25 -> -0.06394264 | R25: =EXP(Q25) -> 0.93805881 | S25: =L25-L24 -> -0.023832242 | T25: -0.028322275
A26: λ1 | B26: =IF((Ni*(Beta1*Mi-((Beta1*Psi)/Theta)-1))^2-4*(Ni*Beta1*Mi)/Theta>0,(Ni*(Beta1*Mi-((Beta1*Psi)/Theta)-1)+SQRT((Ni*(Beta1*Mi-((Beta1*Psi)/Theta)-1))^2-4*(Ni*Beta1*Mi)/Theta))/2,((Ni*(Beta1*Mi-((Beta1*Psi)/Theta)-1))/2)) -> -0.05 | C26: =IF((Ni*((Beta1*Mi-(Beta1*Psi)/Theta)-1)^2-4*(Ni*Beta1*Mi)/Theta)>0, 0, +SQRT(-(Ni*((Beta1*Mi-(Beta1*Psi)/Theta)-1)^2-4*(Ni*Beta1*Mi)/Theta))/2) -> 0.98742088 | E26: 23 | F26: =F25+M25 -> 1.1033974 | G26: =G25+O25 -> 2034.0645 | H26: =Beta0_0 -Beta1*(L26-M26) -> 2049.8141 | I26: =ypot_0*R26 -> 1849.295 | J26: =LN(G26/I26) -> 0.095231505 | K26: =K25+0.1 -> 102.3 | L26: =MAX(0,-1/Theta*(K26-F26-Psi*G26)) -> 1.0132403 | M26: =Mi*LN(G26/(I26)) -> 0.0095231505 | N26: =L26-M26 -> 1.0037171 | O26: =Ni*(H26-G26) -> 1.5749689 | P26: =NORMINV(RAND(), 0, $C$34) -> -0.028108665 | Q26: =$C$33*Q25+T26 -> -0.0783427 | R26: =EXP(Q26) -> 0.9246475 | S26: =L26-L25 -> -0.022141345 | T26: -0.020794324
A27: λ2 | B27: =IF((Ni*(Beta1*Mi-((Beta1*Psi)/Theta)-1))^2-4*(Ni*Beta1*Mi)/Theta>0,(Ni*(Beta1*Mi-((Beta1*Psi)/Theta)-1)-SQRT((Ni*(Beta1*Mi-((Beta1*Psi)/Theta)-1))^2-4*(Ni*Beta1*Mi)/Theta))/2,((Ni*(Beta1*Mi-((Beta1*Psi)/Theta)-1))/2)) -> -0.05 | C27: =IF((Ni*((Beta1*Mi-(Beta1*Psi)/Theta)-1)^2-4*(Ni*Beta1*Mi)/Theta)>0, 0, -SQRT(-(Ni*((Beta1*Mi-(Beta1*Psi)/Theta)-1)^2-4*(Ni*Beta1*Mi)/Theta))/2) -> -0.98742088 | E27: 24 | F27: =F26+M26 -> 1.1129206 | G27: =G26+O26 -> 2035.6394 | H27: =Beta0_0 -Beta1*(L27-M27) -> 2051.4419 | I27: =ypot_0*R27 -> 1689.7665 | J27: =LN(G27/I27) -> 0.18621966 | K27: =K26+0.1 -> 102.4 | L27: =MAX(0,-1/Theta*(K27-F27-Psi*G27)) -> 0.98978348 | M27: =Mi*LN(G27/(I27)) -> 0.018621966 | N27: =L27-M27 -> 0.97116151 | O27: =Ni*(H27-G27) -> 1.5802501 | P27: =NORMINV(RAND(), 0, $C$34) -> -0.048638078 | Q27: =$C$33*Q26+T27 -> -0.16855685 | R27: =EXP(Q27) -> 0.84488323 | S27: =L27-L26 -> -0.023456809 | T27: -0.098048424
E28: 25 | F28: =F27+M27 -> 1.1315426 | G28: =G27+O27 -> 2037.2197 | H28: =Beta0_0 -Beta1*(L28-M28) -> 2051.6922 | I28: =ypot_0*R28 -> 1686.4276 | J28: =LN(G28/I28) -> 0.1889735 | K28: =K27+0.1 -> 102.5 | L28: =MAX(0,-1/Theta*(K28-F28-Psi*G28)) -> 0.98505242 | M28: =Mi*LN(G28/(I28)) -> 0.01889735 | N28: =L28-M28 -> 0.96615507 | O28: =Ni*(H28-G28) -> 1.4472573 | P28: =NORMINV(RAND(), 0, $C$34) -> -0.10672244 | Q28: =$C$33*Q27+T28 -> -0.17053471 | R28: =EXP(Q28) -> 0.84321382 | S28: =L28-L27 -> -0.0047310556 | T28: -0.018833541
A29: Stability condition | E29: 26 | F29: =F28+M28 -> 1.1504399 | G29: =G28+O28 -> 2038.6669 | H29: =Beta0_0 -Beta1*(L29-M29) -> 2052.4182 | I29: =ypot_0*R29 -> 1738.3205 | J29: =LN(G29/I29) -> 0.15937669 | K29: =K28+0.1 -> 102.6 | L29: =MAX(0,-1/Theta*(K29-F29-Psi*G29)) -> 0.96757286 | M29: =Mi*LN(G29/(I29)) -> 0.015937669 | N29: =L29-M29 -> 0.95163519 | O29: =Ni*(H29-G29) -> 1.375131 | P29: =NORMINV(RAND(), 0, $C$34) -> 0.0049406403 | Q29: =$C$33*Q28+T29 -> -0.14022774 | R29: =EXP(Q29) -> 0.86916027 | S29: =L29-L28 -> -0.017479568 | T29: 0.013253502
A30: Modulus (1+λ1) | B30: =IF(C26=0,ABS(1+B26),SQRT((1+B26)^2+C26^2)) -> 1.370219 | E30: 27 | F30: =F29+M29 -> 1.1663776 | G30: =G29+O29 -> 2040.0421 | H30: =Beta0_0 -Beta1*(L30-M30) -> 2053.8382 | I30: =ypot_0*R30 -> 1778.4218 | J30: =LN(G30/I30) -> 0.13724407 | K30: =K29+0.1 -> 102.7 | L30: =MAX(0,-1/Theta*(K30-F30-Psi*G30)) -> 0.9369613 | M30: =Mi*LN(G30/(I30)) -> 0.013724407 | N30: =L30-M30 -> 0.92323689 | O30: =Ni*(H30-G30) -> 1.3796094 | P30: =NORMINV(RAND(), 0, $C$34) -> -0.029626297 | Q30: =$C$33*Q29+T30 -> -0.11742082 | R30: =EXP(Q30) -> 0.88921092 | S30: =L30-L29 -> -0.030611561 | T30: 0.0087841437
A31: Modulus (1+λ2) | B31: =IF(B27=0,ABS(1+B27),SQRT((1+B27)^2+C27^2)) -> 1.370219 | E31: 28 | F31: =F30+M30 -> 1.180102 | G31: =G30+O30 -> 2041.4217 | H31: =Beta0_0 -Beta1*(L31-M31) -> 2055.1795 | I31: =ypot_0*R31 -> 1923.2956 | J31: =LN(G31/I31) -> 0.059606269 | K31: =K30+0.1 -> 102.8 | L31: =MAX(0,-1/Theta*(K31-F31-Psi*G31)) -> 0.90237105 | M31: =Mi*LN(G31/(I31)) -> 0.0059606269 | N31: =L31-M31 -> 0.89641042 | O31: =Ni*(H31-G31) -> 1.3757808 | P31: =NORMINV(RAND(), 0, $C$34) -> -0.061758252 | Q31: =$C$33*Q30+T31 -> -0.039106987 | R31: =EXP(Q31) -> 0.96164782 | S31: =L31-L30 -> -0.034590246 | T31: 0.066571751
E32: 29 | F32: =F31+M31 -> 1.1860626 | G32: =G31+O31 -> 2042.7975 | H32: =Beta0_0 -Beta1*(L32-M32) -> 2057.8278 | I32: =ypot_0*R32 -> 1877.7323 | J32: =LN(G32/I32) -> 0.084255328 | K32: =K31+0.1 -> 102.9 | L32: =MAX(0,-1/Theta*(K32-F32-Psi*G32)) -> 0.85187038 | M32: =Mi*LN(G32/(I32)) -> 0.0084255328 | N32: =L32-M32 -> 0.84344485 | O32: =Ni*(H32-G32) -> 1.5030306 | P32: =NORMINV(RAND(), 0, $C$34) -> 0.0035584459 | Q32: =$C$33*Q31+T32 -> -0.06308234 | R32: =EXP(Q32) -> 0.93886616 | S32: =L32-L31 -> -0.050500666 | T32: -0.027886053
B33: Rho_z | C33: 0.9 | E33: 30 | F33: =F32+M32 -> 1.1944881 | G33: =G32+O32 -> 2044.3005 | H33: =Beta0_0 -Beta1*(L33-M33) -> 2059.3667 | I33: =ypot_0*R33 -> 1918.3762 | J33: =LN(G33/I33) -> 0.063576557 | K33: =K32+0.1 -> 103 | L33: =MAX(0,-1/Theta*(K33-F33-Psi*G33)) -> 0.81902451 | M33: =Mi*LN(G33/(I33)) -> 0.0063576557 | N33: =L33-M33 -> 0.81266685 | O33: =Ni*(H33-G33) -> 1.5066175 | P33: =NORMINV(RAND(), 0, $C$34) -> -0.013825631 | Q33: =$C$33*Q32+T33 -> -0.041668069 | R33: =EXP(Q33) -> 0.95918811 | S33: =L33-L32 -> -0.032845876 | T33: 0.015106037
B34: Std Dev z | C34: 0.05 | E34: 31 | F34: =F33+M33 -> 1.2008458 | G34: =G33+O33 -> 2045.8071 | H34: =Beta0_0 -Beta1*(L34-M34) -> 2061.1127 | I34: =ypot_0*R34 -> 1952.7556 | J34: =LN(G34/I34) -> 0.046550897 | K34: =K33+0.1 -> 103.1 | L34: =MAX(0,-1/Theta*(K34-F34-Psi*G34)) -> 0.78240157 | M34: =Mi*LN(G34/(I34)) -> 0.0046550897 | N34: =L34-M34 -> 0.77774648 | O34: =Ni*(H34-G34) -> 1.5305576 | P34: =NORMINV(RAND(), 0, $C$34) -> -0.05355132 | Q34: =$C$33*Q33+T34 -> -0.023905696 | R34: =EXP(Q34) -> 0.97637778 | S34: =L34-L33 -> -0.036622937 | T34: 0.013595567
E35: 32 | F35: =F34+M34 -> 1.2055009 | G35: =G34+O34 -> 2047.3377 | H35: =Beta0_0 -Beta1*(L35-M35) -> 2063.4852 | I35: =ypot_0*R35 -> 1771.5115 | J35: =LN(G35/I35) -> 0.1447071 | K35: =K34+0.1 -> 103.2 | L35: =MAX(0,-1/Theta*(K35-F35-Psi*G35)) -> 0.74476751 | M35: =Mi*LN(G35/(I35)) -> 0.01447071 | N35: =L35-M35 -> 0.7302968 | O35: =Ni*(H35-G35) -> 1.6147503 | P35: =NORMINV(RAND(), 0, $C$34) -> 0.061811668 | Q35: =$C$33*Q34+T35 -> -0.12131403 | R35: =EXP(Q35) -> 0.88575576 | S35: =L35-L34 -> -0.037634059 | T35: -0.099798906
E36: 33 | F36: =F35+M35 -> 1.2199716 | G36: =G35+O35 -> 2048.9524 | H36: =Beta0_0 -Beta1*(L36-M36) -> 2064.0915 | I36: =ypot_0*R36 -> 1728.4032 | J36: =LN(G36/I36) -> 0.17013064 | K36: =K35+0.1 -> 103.3 | L36: =MAX(0,-1/Theta*(K36-F36-Psi*G36)) -> 0.73518396 | M36: =Mi*LN(G36/(I36)) -> 0.017013064 | N36: =L36-M36 -> 0.71817089 | O36: =Ni*(H36-G36) -> 1.5139048 | P36: =NORMINV(RAND(), 0, $C$34) -> -0.0039967133 | Q36: =$C$33*Q35+T36 -> -0.14594918 | R36: =EXP(Q36) -> 0.86420162 | S36: =L36-L35 -> -0.0095835554 | T36: -0.036766554
E37: 34 | F37: =F36+M36 -> 1.2369847 | G37: =G36+O36 -> 2050.4663 | H37: =Beta0_0 -Beta1*(L37-M37) -> 2064.6448 | I37: =ypot_0*R37 -> 1791.6018 | J37: =LN(G37/I37) -> 0.13495717 | K37: =K36+0.1 -> 103.4 | L37: =MAX(0,-1/Theta*(K37-F37-Psi*G37)) -> 0.72060056 | M37: =Mi*LN(G37/(I37)) -> 0.013495717 | N37: =L37-M37 -> 0.70710485 | O37: =Ni*(H37-G37) -> 1.4178445 | P37: =NORMINV(RAND(), 0, $C$34) -> -0.11545842 | Q37: =$C$33*Q36+T37 -> -0.11003711 | R37: =EXP(Q37) -> 0.89580089 | S37: =L37-L36 -> -0.014583393 | T37: 0.021317151
E38: 35 | F38: =F37+M37 -> 1.2504804 | G38: =G37+O37 -> 2051.8842 | H38: =Beta0_0 -Beta1*(L38-M38) -> 2066.6245 | I38: =ypot_0*R38 -> 1648.8634 | J38: =LN(G38/I38) -> 0.21867224 | K38: =K37+0.1 -> 103.5 | L38: =MAX(0,-1/Theta*(K38-F38-Psi*G38)) -> 0.68937645 | M38: =Mi*LN(G38/(I38)) -> 0.021867224 | N38: =L38-M38 -> 0.66750923 | O38: =Ni*(H38-G38) -> 1.4740382 | P38: =NORMINV(RAND(), 0, $C$34) -> -0.073591785 | Q38: =$C$33*Q37+T38 -> -0.19306095 | R38: =EXP(Q38) -> 0.82443172 | S38: =L38-L37 -> -0.031224113 | T38: -0.094027551
E39: 36 | F39: =F38+M38 -> 1.2723476 | G39: =G38+O38 -> 2053.3582 | H39: =Beta0_0 -Beta1*(L39-M39) -> 2066.8651 | I39: =ypot_0*R39 -> 1718.2644 | J39: =LN(G39/I39) -> 0.17816187 | K39: =K38+0.1 -> 103.6 | L39: =MAX(0,-1/Theta*(K39-F39-Psi*G39)) -> 0.68051472 | M39: =Mi*LN(G39/(I39)) -> 0.017816187 | N39: =L39-M39 -> 0.66269853 | O39: =Ni*(H39-G39) -> 1.3506878 | P39: =NORMINV(RAND(), 0, $C$34) -> -0.06729214 | Q39: =$C$33*Q38+T39 -> -0.15183245 | R39: =EXP(Q39) -> 0.85913221 | S39: =L39-L38 -> -0.0088617331 | T39: 0.021922405
E40: 37 | F40: =F39+M39 -> 1.2901638 | G40: =G39+O39 -> 2054.7089 | H40: =Beta0_0 -Beta1*(L40-M40) -> 2068.5863 | I40: =ypot_0*R40 -> 1633.4807 | J40: =LN(G40/I40) -> 0.22942106 | K40: =K39+0.1 -> 103.7 | L40: =MAX(0,-1/Theta*(K40-F40-Psi*G40)) -> 0.65121588 | M40: =Mi*LN(G40/(I40)) -> 0.022942106 | N40: =L40-M40 -> 0.62827377 | O40: =Ni*(H40-G40) -> 1.3877429 | P40: =NORMINV(RAND(), 0, $C$34) -> -0.068782832 | Q40: =$C$33*Q39+T40 -> -0.20243406 | R40: =EXP(Q40) -> 0.81674033 | S40: =L40-L39 -> -0.029298842 | T40: -0.065784857
...

Sheet Sheet2
A1: RTFPNAUSA632NRUG | H1: RTFPNAUSA632NRUG
A2: lin | B2: Index 2017=1, Not Seasonally Adjusted | H2: lin
A3: a | B3: Annual | H3: a
A4: 19725 | B4: 1954-01-01 to 2019-01-01 | H4: 19725
A5: Total Factor Productivity at Constant National Prices for United States | H5: Total Factor Productivity at Constant National Prices for United States
A6: University of Groningen, University of California, Davis | H6: University of Groningen, University of California, Davis
B7: value
A8: 19725 | B8: 0.6514501 | I8: TFP
A9: 20090 | B9: 0.67253059 | C9: =LN(B9)-LN(B8) -> 0.031846802 | H9: 20090 | I9: 0.031846802
A10: 20455 | B10: 0.66870439 | C10: =LN(B10)-LN(B9) -> -0.0057055048 | H10: 20455 | I10: -0.0057055048
A11: 20821 | B11: 0.67597854 | C11: =LN(B11)-LN(B10) -> 0.010819237 | H11: 20821 | I11: 0.010819237
A12: 21186 | B12: 0.67719972 | C12: =LN(B12)-LN(B11) -> 0.0018049068 | H12: 21186 | I12: 0.0018049068
A13: 21551 | B13: 0.69634539 | C13: =LN(B13)-LN(B12) -> 0.027879547 | H13: 21551 | I13: 0.027879547
A14: 21916 | B14: 0.70009267 | C14: =LN(B14)-LN(B13) -> 0.0053669311 | H14: 21916 | I14: 0.0053669311
A15: 22282 | B15: 0.70670336 | C15: =LN(B15)-LN(B14) -> 0.0093982923 | H15: 22282 | I15: 0.0093982923
A16: 22647 | B16: 0.72234893 | C16: =LN(B16)-LN(B15) -> 0.021897294 | H16: 22647 | I16: 0.021897294
A17: 23012 | B17: 0.73288095 | C17: =LN(B17)-LN(B16) -> 0.014474971 | H17: 23012 | I17: 0.014474971
A18: 23377 | B18: 0.74438596 | C18: =LN(B18)-LN(B17) -> 0.015576387 | H18: 23377 | I18: 0.015576387
A19: 23743 | B19: 0.75609702 | C19: =LN(B19)-LN(B18) -> 0.015610039 | H19: 23743 | I19: 0.015610039
A20: 24108 | B20: 0.76762307 | C20: =LN(B20)-LN(B19) -> 0.015129115 | H20: 24108 | I20: 0.015129115
... A73: 43466 | B73: 1.0167962 | C73: =LN(B73)-LN(B72) -> 0.0085239399 | H73: 43466 | I73: 0.0085239399
C74: =AVERAGE(C9:C73) -> 0.0068494033 | I74: 0.0068494033
C75: =STDEV(C9:C73) -> 0.010774617 | I75: 0.010774617

Sheet Base Prod-Interest Rate I
A1: EXERCISE 2: Dynamic IS-LM model with a Recurring Productivity Shock and Fixed Interest Rate | T1: fixed ep
E2: Time | F2: p | G2: y | H2: yn | I2: gap | J2: yd | K2: m | L2: i | M2: ∆p | N2: Real i | O2: ∆y | P2: epsilon | Q2: z | R2: Z | S2: ∆i | T2: epsilon
A3: Endogenous variables | B3: Change over time | E3: 0 | F3: =(Theta*Beta0_0)/Beta1+m_0-(Psi+Theta/Beta1)*ypot_0 -> 1 | G3: =ypot_0 -> 2000 | H3: =$C$19*R3 -> 2000 | I3: =LN(G3/H3) -> 0 | J3: =Beta0_0-Beta1*(L3-M3) -> 2000 | K3: =F3*($B$11*G3-$B$12*M3) -> 1000 | L3: =2 -> 2 | M3: =Mi*I3 -> 0 | N3: =L3-M3 -> 2 | O3: =Ni*(J3-G3) -> 0 | P3: 0 | Q3: 0 | R3: 1 | S3: 0 | T3: 0
A4: p: Price level | B4: ∆p: Inflation | E4: 1 | F4: =F3+M3 -> 1 | G4: =G3+O3 -> 2000 | H4: =$C$19*R4 -> 2000 | I4: =LN(G4/H4) -> 0 | J4: =Beta0_1-Beta1*(L4-M4) -> 2000 | K4: =F4*($B$11*G4-$B$12*M4) -> 1000 | L4: =2 -> 2 | M4: =Mi*I4 -> 0 | N4: =L4-M4 -> 2 | O4: =Ni*(J4-G4) -> 0 | P4: ='Fixing Money'!P4 -> 0 | Q4: =$C$33*Q3+T4 -> 0 | R4: =EXP(Q4) -> 1 | S4: =L4-L3 -> 0 | T4: 0
A5: y: Output | B5: ∆y: Output growth | E5: 2 | F5: =F4+M4 -> 1 | G5: =G4+O4 -> 2000 | H5: =$C$19*R5 -> 1918.1403 | I5: =LN(G5/H5) -> 0.041791046 | J5: =Beta0_1-Beta1*(L5-M5) -> 2000.209 | K5: =F5*($B$11*G5-$B$12*M5) -> 999.79104 | L5: =2 -> 2 | M5: =Mi*I5 -> 0.0041791046 | N5: =L5-M5 -> 1.9958209 | O5: =Ni*(J5-G5) -> 0.020895523 | P5: ='Fixing Money'!P5 -> -0.032427153 | Q5: =$C$33*Q4+T5 -> -0.041791046 | R5: =EXP(Q5) -> 0.95907016 | S5: =L5-L4 -> 0 | T5: -0.041791046
A6: yd: Aggregate demand | E6: 3 | F6: =F5+M5 -> 1.0041791 | G6: =G5+O5 -> 2000.0209 | H6: =$C$19*R6 -> 1915.0047 | I6: =LN(G6/H6) -> 0.043437568 | J6: =Beta0_1-Beta1*(L6-M6) -> 2000.2172 | K6: =F6*($B$11*G6-$B$12*M6) -> 1003.9715 | L6: =2 -> 2 | M6: =Mi*I6 -> 0.0043437568 | N6: =L6-M6 -> 1.9956562 | O6: =Ni*(J6-G6) -> 0.019629232 | P6: ='Fixing Money'!P6 -> 0.063067809 | Q6: =$C$33*Q5+T6 -> -0.043427121 | R6: =EXP(Q6) -> 0.95750233 | S6: =L6-L5 -> 0 | T6: -0.0037256268
A7: i: Nominal interest rate | E7: 4 | F7: =F6+M6 -> 1.0085229 | G7: =G6+O6 -> 2000.0405 | H7: =$C$19*R7 -> 1861.9896 | I7: =LN(G7/H7) -> 0.071521869 | J7: =Beta0_1-Beta1*(L7-M7) -> 2000.3576 | K7: =F7*($B$11*G7-$B$12*M7) -> 1008.1826 | L7: =2 -> 2 | M7: =Mi*I7 -> 0.0071521869 | N7: =L7-M7 -> 1.9928478 | O7: =Ni*(J7-G7) -> 0.031708459 | P7: ='Fixing Money'!P7 -> 0.17506394 | Q7: =$C$33*Q6+T7 -> -0.071501607 | R7: =EXP(Q7) -> 0.93099478 | S7: =L7-L6 -> 0 | T7: -0.030245842
E8: 5 | F8: =F7+M7 -> 1.015675 | G8: =G7+O7 -> 2000.0722 | H8: =$C$19*R8 -> 1899.5451 | I8: =LN(G8/H8) -> 0.051568855 | J8: =Beta0_1-Beta1*(L8-M8) -> 2000.2578 | K8: =F8*($B$11*G8-$B$12*M8) -> 1015.4498 | L8: =2 -> 2 | M8: =Mi*I8 -> 0.0051568855 | N8: =L8-M8 -> 1.9948431 | O8: =Ni*(J8-G8) -> 0.018561106 | P8: ='Fixing Money'!P8 -> -0.015373145 | Q8: =$C$33*Q7+T8 -> -0.051532739 | R8: =EXP(Q8) -> 0.94977256 | S8: =L8-L7 -> 0 | T8: 0.016393788
A9: Parameters | E9: 6 | F9: =F8+M8 -> 1.0208319 | G9: =G8+O8 -> 2000.0908 | H9: =$C$19*R9 -> 1837.9078 | I9: =LN(G9/H9) -> 0.084564695 | J9: =Beta0_1-Beta1*(L9-M9) -> 2000.4228 | K9: =F9*($B$11*G9-$B$12*M9) -> 1020.4466 | L9: =2 -> 2 | M9: =Mi*I9 -> 0.0084564695 | N9: =L9-M9 -> 1.9915435 | O9: =Ni*(J9-G9) -> 0.033202916 | P9: ='Fixing Money'!P9 -> -0.039132545 | Q9: =$C$33*Q8+T9 -> -0.084519299 | R9: =EXP(Q9) -> 0.91895392 | S9: =L9-L8 -> 0 | T9: -0.035563197
A10: Psi | B10: 0.05 | E10: 7 | F10: =F9+M9 -> 1.0292884 | G10: =G9+O9 -> 2000.124 | H10: =$C$19*R10 -> 1910.5672 | I10: =LN(G10/H10) -> 0.045809012 | J10: =Beta0_1-Beta1*(L10-M10) -> 2000.229 | K10: =F10*($B$11*G10-$B$12*M10) -> 1029.1165 | L10: =2 -> 2 | M10: =Mi*I10 -> 0.0045809012 | N10: =L10-M10 -> 1.9954191 | O10: =Ni*(J10-G10) -> 0.010504782 | P10: ='Fixing Money'!P10 -> -0.0063226409 | Q10: =$C$33*Q9+T10 -> -0.045747015 | R10: =EXP(Q10) -> 0.9552836 | S10: =L10-L9 -> 0 | T10: 0.034546319
A11: Theta | B11: 0.5 | E11: 8 | F11: =F10+M10 -> 1.0338693 | G11: =G10+O10 -> 2000.1345 | H11: =$C$19*R11 -> 2062.3793 | I11: =LN(G11/H11) -> -0.030645866 | J11: =Beta0_1-Beta1*(L11-M11) -> 1999.8468 | K11: =F11*($B$11*G11-$B$12*M11) -> 1034.0973 | L11: =2 -> 2 | M11: =Mi*I11 -> -0.0030645866 | N11: =L11-M11 -> 2.0030646 | O11: =Ni*(J11-G11) -> -0.028773135 | P11: ='Fixing Money'!P11 -> -0.022154893 | Q11: =$C$33*Q10+T11 -> 0.030713115 | R11: =EXP(Q11) -> 1.0311896 | S11: =L11-L10 -> 0 | T11: 0.074172779
A12: Beta1 | B12: 50 | E12: 9 | F12: =F11+M11 -> 1.0308047 | G12: =G11+O11 -> 2000.1057 | H12: =$C$19*R12 -> 2140.8542 | I12: =LN(G12/H12) -> -0.068004887 | J12: =Beta0_1-Beta1*(L12-M12) -> 1999.66 | K12: =F12*($B$11*G12-$B$12*M12) -> 1031.2097 | L12: =2 -> 2 | M12: =Mi*I12 -> -0.0068004887 | N12: =L12-M12 -> 2.0068005 | O12: =Ni*(J12-G12) -> -0.044575332 | P12: ='Fixing Money'!P12 -> 0.058675604 | Q12: =$C$33*Q11+T12 -> 0.06805775 | R12: =EXP(Q12) -> 1.0704271 | S12: =L12-L11 -> 0 | T12: 0.038880291
A13: Mi | B13: 0.1 | E13: 10 | F13: =F12+M12 -> 1.0240042 | G13: =G12+O12 -> 2000.0612 | H13: =$C$19*R13 -> 2034.0884 | I13: =LN(G13/H13) -> -0.016869992 | J13: =Beta0_1-Beta1*(L13-M13) -> 1999.9157 | K13: =F13*($B$11*G13-$B$12*M13) -> 1024.1219 | L13: =2 -> 2 | M13: =Mi*I13 -> -0.0016869992 | N13: =L13-M13 -> 2.001687 | O13: =Ni*(J13-G13) -> -0.014550351 | P13: ='Fixing Money'!P13 -> 0.11716061 | Q13: =$C$33*Q12+T13 -> 0.016900569 | R13: =EXP(Q13) -> 1.0170442 | S13: =L13-L12 -> 0 | T13: -0.047754294
A14: Ni | B14: 0.1 | E14: 11 | F14: =F13+M13 -> 1.0223172 | G14: =G13+O13 -> 2000.0466 | H14: =$C$19*R14 -> 1914.758 | I14: =LN(G14/H14) -> 0.043579257 | J14: =Beta0_1-Beta1*(L14-M14) -> 2000.2179 | K14: =F14*($B$11*G14-$B$12*M14) -> 1022.1183 | L14: =2 -> 2 | M14: =Mi*I14 -> 0.0043579257 | N14: =L14-M14 -> 1.9956421 | O14: =Ni*(J14-G14) -> 0.017129309 | P14: ='Fixing Money'!P14 -> 0.040820445 | Q14: =$C$33*Q13+T14 -> -0.043555956 | R14: =EXP(Q14) -> 0.95737898 | S14: =L14-L13 -> 0 | T14: -0.059611496
E15: 12 | F15: =F14+M14 -> 1.0266752 | G15: =G14+O14 -> 2000.0637 | H15: =$C$19*R15 -> 1792.6735 | I15: =LN(G15/H15) -> 0.10947096 | J15: =Beta0_1-Beta1*(L15-M15) -> 2000.5474 | K15: =F15*($B$11*G15-$B$12*M15) -> 1026.1459 | L15: =2 -> 2 | M15: =Mi*I15 -> 0.010947096 | N15: =L15-M15 -> 1.9890529 | O15: =Ni*(J15-G15) -> 0.048362228 | P15: ='Fixing Money'!P15 -> 0.065941603 | Q15: =$C$33*Q14+T15 -> -0.10943909 | R15: =EXP(Q15) -> 0.89633676 | S15: =L15-L14 -> 0 | T15: -0.068060934
A16: Exogenous variables | B16: Initial value | C16: Final value | E16: 13 | F16: =F15+M15 -> 1.0376223 | G16: =G15+O15 -> 2000.1121 | H16: =$C$19*R16 -> 1960.9371 | I16: =LN(G16/H16) -> 0.019780766 | J16: =Beta0_1-Beta1*(L16-M16) -> 2000.0989 | K16: =F16*($B$11*G16-$B$12*M16) -> 1037.5778 | L16: =2 -> 2 | M16: =Mi*I16 -> 0.0019780766 | N16: =L16-M16 -> 1.9980219 | O16: =Ni*(J16-G16) -> -0.0013190906 | P16: ='Fixing Money'!P16 -> -0.08553997 | Q16: =$C$33*Q15+T16 -> -0.01972472 | R16: =EXP(Q16) -> 0.98046854 | S16: =L16-L15 -> 0 | T16: 0.084242417
A17: m: Money | B17: 100 | C17: 100 | E17: 14 | F17: =F16+M16 -> 1.0396003 | G17: =G16+O16 -> 2000.1108 | H17: =$C$19*R17 -> 1804.0116 | I17: =LN(G17/H17) -> 0.10318972 | J17: =Beta0_1-Beta1*(L17-M17) -> 2000.5159 | K17: =F17*($B$11*G17-$B$12*M17) -> 1039.1215 | L17: =2 -> 2 | M17: =Mi*I17 -> 0.010318972 | N17: =L17-M17 -> 1.989681 | O17: =Ni*(J17-G17) -> 0.040517295 | P17: ='Fixing Money'!P17 -> -0.025298068 | Q17: =$C$33*Q16+T17 -> -0.10313433 | R17: =EXP(Q17) -> 0.9020058 | S17: =L17-L16 -> 0 | T17: -0.084395848
A18: Beta0: Government spending | B18: 2100 | C18: 2100 | E18: 15 | F18: =F17+M17 -> 1.0499193 | G18: =G17+O17 -> 2000.1513 | H18: =$C$19*R18 -> 1776.9211 | I18: =LN(G18/H18) -> 0.11834067 | J18: =Beta0_1-Beta1*(L18-M18) -> 2000.5917 | K18: =F18*($B$11*G18-$B$12*M18) -> 1049.3775 | L18: =2 -> 2 | M18: =Mi*I18 -> 0.011834067 | N18: =L18-M18 -> 1.9881659 | O18: =Ni*(J18-G18) -> 0.044041039 | P18: ='Fixing Money'!P18 -> -0.011113111 | Q18: =$C$33*Q17+T18 -> -0.11826502 | R18: =EXP(Q18) -> 0.88846056 | S18: =L18-L17 -> 0 | T18: -0.020287407
A19: Ypot: Potential output | B19: 2000 | C19: 2000 | E19: 16 | F19: =F18+M18 -> 1.0617534 | G19: =G18+O18 -> 2000.1953 | H19: =$C$19*R19 -> 1770.7316 | I19: =LN(G19/H19) -> 0.12185203 | J19: =Beta0_1-Beta1*(L19-M19) -> 2000.6093 | K19: =F19*($B$11*G19-$B$12*M19) -> 1061.2102 | L19: =2 -> 2 | M19: =Mi*I19 -> 0.012185203 | N19: =L19-M19 -> 1.9878148 | O19: =Ni*(J19-G19) -> 0.041392616 | P19: ='Fixing Money'!P19 -> 0.060955149 | Q19: =$C$33*Q18+T19 -> -0.12175437 | R19: =EXP(Q19) -> 0.88536582 | S19: =L19-L18 -> 0 | T19: -0.0094025934
E20: 17 | F20: =F19+M19 -> 1.0739386 | G20: =G19+O19 -> 2000.2367 | H20: =$C$19*R20 -> 1763.0348 | I20: =LN(G20/H20) -> 0.12622887 | J20: =Beta0_1-Beta1*(L20-M20) -> 2000.6311 | K20: =F20*($B$11*G20-$B$12*M20) -> 1073.3879 | L20: =2 -> 2 | M20: =Mi*I20 -> 0.012622887 | N20: =L20-M20 -> 1.9873771 | O20: =Ni*(J20-G20) -> 0.039441774 | P20: ='Fixing Money'!P20 -> -0.034670115 | Q20: =$C$33*Q19+T20 -> -0.12611051 | R20: =EXP(Q20) -> 0.88151742 | S20: =L20-L19 -> 0 | T20: -0.010443865
A21: Steady State | B21: Initial SS | C21: Final SS | E21: 18 | F21: =F20+M20 -> 1.0865615 | G21: =G20+O20 -> 2000.2762 | H21: =$C$19*R21 -> 1872.0644 | I21: =LN(G21/H21) -> 0.066243483 | J21: =Beta0_1-Beta1*(L21-M21) -> 2000.3312 | K21: =F21*($B$11*G21-$B$12*M21) -> 1086.3516 | L21: =2 -> 2 | M21: =Mi*I21 -> 0.0066243483 | N21: =L21-M21 -> 1.9933757 | O21: =Ni*(J21-G21) -> 0.0055049043 | P21: ='Fixing Money'!P21 -> -0.010745592 | Q21: =$C$33*Q20+T21 -> -0.066105408 | R21: =EXP(Q21) -> 0.93603219 | S21: =L21-L20 -> 0 | T21: 0.053699578
A22: Steady state for p | B22: =(Theta*Beta0_0)/Beta1+m_0-(Psi+Theta/Beta1)*ybar0 -> 1 | C22: =(Theta*Beta0_1)/Beta1+m_1-(Psi+Theta/Beta1)*ybar1 -> 1 | E22: 19 | F22: =F21+M21 -> 1.0931858 | G22: =G21+O21 -> 2000.2817 | H22: =$C$19*R22 -> 1890.4639 | I22: =LN(G22/H22) -> 0.056465764 | J22: =Beta0_1-Beta1*(L22-M22) -> 2000.2823 | K22: =F22*($B$11*G22-$B$12*M22) -> 1093.0311 | L22: =2 -> 2 | M22: =Mi*I22 -> 0.0056465764 | N22: =L22-M22 -> 1.9943534 | O22: =Ni*(J22-G22) -> 6.5554363e-05 | P22: ='Fixing Money'!P22 -> -0.03327487 | Q22: =$C$33*Q21+T22 -> -0.056324937 | R22: =EXP(Q22) -> 0.94523195 | S22: =L22-L21 -> 0 | T22: 0.0064752007
A23: Steady state for y | B23: =ypot0 -> 2000 | C23: =ypot1 -> 2000 | E23: 20 | F23: =F22+M22 -> 1.0988324 | G23: =G22+O22 -> 2000.2817 | H23: =$C$19*R23 -> 1981.9893 | I23: =LN(G23/H23) -> 0.0091870035 | J23: =Beta0_1-Beta1*(L23-M23) -> 2000.0459 | K23: =F23*($B$11*G23-$B$12*M23) -> 1098.9367 | L23: =2 -> 2 | M23: =Mi*I23 -> 0.00091870035 | N23: =L23-M23 -> 1.9990813 | O23: =Ni*(J23-G23) -> -0.023580381 | P23: ='Fixing Money'!P23 -> 0.04242673 | Q23: =$C$33*Q22+T23 -> -0.009046144 | R23: =EXP(Q23) -> 0.99099465 | S23: =L23-L22 -> 0 | T23: 0.044462546
E24: 21 | F24: =F23+M23 -> 1.0997511 | G24: =G23+O23 -> 2000.2582 | H24: =$C$19*R24 -> 1873.4658 | I24: =LN(G24/H24) -> 0.06548616 | J24: =Beta0_1-Beta1*(L24-M24) -> 2000.3274 | K24: =F24*($B$11*G24-$B$12*M24) -> 1099.5329 | L24: =2 -> 2 | M24: =Mi*I24 -> 0.006548616 | N24: =L24-M24 -> 1.9934514 | O24: =Ni*(J24-G24) -> 0.0069272354 | P24: ='Fixing Money'!P24 -> 0.097560915 | Q24: =$C$33*Q23+T24 -> -0.06535709 | R24: =EXP(Q24) -> 0.93673291 | S24: =L24-L23 -> 0 | T24: -0.056763253
A25: Eigenvalues | B25: Real | C25: Imaginary | E25: 22 | F25: =F24+M24 -> 1.1062997 | G25: =G24+O24 -> 2000.2651 | H25: =$C$19*R25 -> 1827.1103 | I25: =LN(G25/H25) -> 0.090544044 | J25: =Beta0_1-Beta1*(L25-M25) -> 2000.4527 | K25: =F25*($B$11*G25-$B$12*M25) -> 1105.9455 | L25: =2 -> 2 | M25: =Mi*I25 -> 0.0090544044 | N25: =L25-M25 -> 1.9909456 | O25: =Ni*(J25-G25) -> 0.018763454 | P25: ='Fixing Money'!P25 -> -0.043523728 | Q25: =$C$33*Q24+T25 -> -0.09041151 | R25: =EXP(Q25) -> 0.91355517 | S25: =L25-L24 -> 0 | T25: -0.028322275
A26: λ1 | B26: =IF((Ni*(Beta1*Mi-((Beta1*Psi)/Theta)-1))^2-4*(Ni*Beta1*Mi)/Theta>0,(Ni*(Beta1*Mi-((Beta1*Psi)/Theta)-1)+SQRT((Ni*(Beta1*Mi-((Beta1*Psi)/Theta)-1))^2-4*(Ni*Beta1*Mi)/Theta))/2,((Ni*(Beta1*Mi-((Beta1*Psi)/Theta)-1))/2)) -> -0.05 | C26: =IF((Ni*((Beta1*Mi-(Beta1*Psi)/Theta)-1)^2-4*(Ni*Beta1*Mi)/Theta)>0, 0, +SQRT(-(Ni*((Beta1*Mi-(Beta1*Psi)/Theta)-1)^2-4*(Ni*Beta1*Mi)/Theta))/2) -> 0.98742088 | E26: 23 | F26: =F25+M25 -> 1.1153541 | G26: =G25+O25 -> 2000.2838 | H26: =$C$19*R26 -> 1797.617 | I26: =LN(G26/H26) -> 0.10682717 | J26: =Beta0_1-Beta1*(L26-M26) -> 2000.5341 | K26: =F26*($B$11*G26-$B$12*M26) -> 1114.9166 | L26: =2 -> 2 | M26: =Mi*I26 -> 0.010682717 | N26: =L26-M26 -> 1.9893173 | O26: =Ni*(J26-G26) -> 0.025028673 | P26: ='Fixing Money'!P26 -> -0.028108665 | Q26: =$C$33*Q25+T26 -> -0.10668526 | R26: =EXP(Q26) -> 0.89880852 | S26: =L26-L25 -> 0 | T26: -0.020794324
A27: λ2 | B27: =IF((Ni*(Beta1*Mi-((Beta1*Psi)/Theta)-1))^2-4*(Ni*Beta1*Mi)/Theta>0,(Ni*(Beta1*Mi-((Beta1*Psi)/Theta)-1)-SQRT((Ni*(Beta1*Mi-((Beta1*Psi)/Theta)-1))^2-4*(Ni*Beta1*Mi)/Theta))/2,((Ni*(Beta1*Mi-((Beta1*Psi)/Theta)-1))/2)) -> -0.05 | C27: =IF((Ni*((Beta1*Mi-(Beta1*Psi)/Theta)-1)^2-4*(Ni*Beta1*Mi)/Theta)>0, 0, -SQRT(-(Ni*((Beta1*Mi-(Beta1*Psi)/Theta)-1)^2-4*(Ni*Beta1*Mi)/Theta))/2) -> -0.98742088 | E27: 24 | F27: =F26+M26 -> 1.1260368 | G27: =G26+O26 -> 2000.3089 | H27: =$C$19*R27 -> 1638.4452 | I27: =LN(G27/H27) -> 0.19955385 | J27: =Beta0_1-Beta1*(L27-M27) -> 2000.9978 | K27: =F27*($B$11*G27-$B$12*M27) -> 1125.0872 | L27: =2 -> 2 | M27: =Mi*I27 -> 0.019955385 | N27: =L27-M27 -> 1.9800446 | O27: =Ni*(J27-G27) -> 0.068889142 | P27: ='Fixing Money'!P27 -> -0.048638078 | Q27: =$C$33*Q26+T27 -> -0.19939942 | R27: =EXP(Q27) -> 0.81922261 | S27: =L27-L26 -> 0 | T27: -0.098048424
E28: 25 | F28: =F27+M27 -> 1.1459922 | G28: =G27+O27 -> 2000.3778 | H28: =$C$19*R28 -> 1623.9869 | I28: =LN(G28/H28) -> 0.20845186 | J28: =Beta0_1-Beta1*(L28-M28) -> 2001.0423 | K28: =F28*($B$11*G28-$B$12*M28) -> 1145.0142 | L28: =2 -> 2 | M28: =Mi*I28 -> 0.020845186 | N28: =L28-M28 -> 1.9791548 | O28: =Ni*(J28-G28) -> 0.066449233 | P28: ='Fixing Money'!P28 -> -0.10672244 | Q28: =$C$33*Q27+T28 -> -0.20826299 | R28: =EXP(Q28) -> 0.81199346 | S28: =L28-L27 -> 0 | T28: -0.018833541
A29: Stability condition | E29: 26 | F29: =F28+M28 -> 1.1668374 | G29: =G28+O28 -> 2000.4442 | H29: =$C$19*R29 -> 1662.8797 | I29: =LN(G29/H29) -> 0.18481842 | J29: =Beta0_1-Beta1*(L29-M29) -> 2000.9241 | K29: =F29*($B$11*G29-$B$12*M29) -> 1166.0183 | L29: =2 -> 2 | M29: =Mi*I29 -> 0.018481842 | N29: =L29-M29 -> 1.9815182 | O29: =Ni*(J29-G29) -> 0.047987593 | P29: ='Fixing Money'!P29 -> 0.0049406403 | Q29: =$C$33*Q28+T29 -> -0.18459634 | R29: =EXP(Q29) -> 0.83143984 | S29: =L29-L28 -> 0 | T29: 0.013253502
A30: Modulus (1+λ1) | B30: =IF(C26=0,ABS(1+B26),SQRT((1+B26)^2+C26^2)) -> 1.370219 | E30: 27 | F30: =F29+M29 -> 1.1853192 | G30: =G29+O29 -> 2000.4922 | H30: =$C$19*R30 -> 1693.1062 | I30: =LN(G30/H30) -> 0.16682845 | J30: =Beta0_1-Beta1*(L30-M30) -> 2000.8341 | K30: =F30*($B$11*G30-$B$12*M30) -> 1184.6222 | L30: =2 -> 2 | M30: =Mi*I30 -> 0.016682845 | N30: =L30-M30 -> 1.9833172 | O30: =Ni*(J30-G30) -> 0.034193847 | P30: ='Fixing Money'!P30 -> -0.029626297 | Q30: =$C$33*Q29+T30 -> -0.16658238 | R30: =EXP(Q30) -> 0.84655308 | S30: =L30-L29 -> 0 | T30: 0.0087841437
A31: Modulus (1+λ2) | B31: =IF(B27=0,ABS(1+B27),SQRT((1+B27)^2+C27^2)) -> 1.370219 | E31: 28 | F31: =F30+M30 -> 1.2020021 | G31: =G30+O30 -> 2000.5264 | H31: =$C$19*R31 -> 1824.7914 | I31: =LN(G31/H31) -> 0.091944672 | J31: =Beta0_1-Beta1*(L31-M31) -> 2000.4597 | K31: =F31*($B$11*G31-$B$12*M31) -> 1201.7659 | L31: =2 -> 2 | M31: =Mi*I31 -> 0.0091944672 | N31: =L31-M31 -> 1.9908055 | O31: =Ni*(J31-G31) -> -0.0066674264 | P31: ='Fixing Money'!P31 -> -0.061758252 | Q31: =$C$33*Q30+T31 -> -0.091681508 | R31: =EXP(Q31) -> 0.91239569 | S31: =L31-L30 -> 0 | T31: 0.066571751
E32: 29 | F32: =F31+M31 -> 1.2111965 | G32: =G31+O31 -> 2000.5197 | H32: =$C$19*R32 -> 1782.7617 | I32: =LN(G32/H32) -> 0.11524332 | J32: =Beta0_1-Beta1*(L32-M32) -> 2000.5762 | K32: =F32*($B$11*G32-$B$12*M32) -> 1210.8134 | L32: =2 -> 2 | M32: =Mi*I32 -> 0.011524332 | N32: =L32-M32 -> 1.9884757 | O32: =Ni*(J32-G32) -> 0.0056486384 | P32: ='Fixing Money'!P32 -> 0.0035584459 | Q32: =$C$33*Q31+T32 -> -0.11498349 | R32: =EXP(Q32) -> 0.89138086 | S32: =L32-L31 -> 0 | T32: -0.027886053
B33: Rho_z | C33: 0.95 | E33: 30 | F33: =F32+M32 -> 1.2227209 | G33: =G32+O32 -> 2000.5254 | H33: =$C$19*R33 -> 1820.332 | I33: =LN(G33/H33) -> 0.094390929 | J33: =Beta0_1-Beta1*(L33-M33) -> 2000.472 | K33: =F33*($B$11*G33-$B$12*M33) -> 1222.465 | L33: =2 -> 2 | M33: =Mi*I33 -> 0.0094390929 | N33: =L33-M33 -> 1.9905609 | O33: =Ni*(J33-G33) -> -0.0053424192 | P33: ='Fixing Money'!P33 -> -0.013825631 | Q33: =$C$33*Q32+T33 -> -0.094128274 | R33: =EXP(Q33) -> 0.910166 | S33: =L33-L32 -> 0 | T33: 0.015106037
B34: Std Dev z | C34: 0.05 | E34: 31 | F34: =F33+M33 -> 1.23216 | G34: =G33+O33 -> 2000.52 | H34: =$C$19*R34 -> 1853.9544 | I34: =LN(G34/H34) -> 0.076086278 | J34: =Beta0_1-Beta1*(L34-M34) -> 2000.3804 | K34: =F34*($B$11*G34-$B$12*M34) -> 1232.0116 | L34: =2 -> 2 | M34: =Mi*I34 -> 0.0076086278 | N34: =L34-M34 -> 1.9923914 | O34: =Ni*(J34-G34) -> -0.013960503 | P34: ='Fixing Money'!P34 -> -0.05355132 | Q34: =$C$33*Q33+T34 -> -0.075826293 | R34: =EXP(Q34) -> 0.92697721 | S34: =L34-L33 -> 0 | T34: 0.013595567
E35: 32 | F35: =F34+M34 -> 1.2397686 | G35: =G34+O34 -> 2000.5061 | H35: =$C$19*R35 -> 1684.2381 | I35: =LN(G35/H35) -> 0.17208689 | J35: =Beta0_1-Beta1*(L35-M35) -> 2000.8604 | K35: =F35*($B$11*G35-$B$12*M35) -> 1239.0156 | L35: =2 -> 2 | M35: =Mi*I35 -> 0.017208689 | N35: =L35-M35 -> 1.9827913 | O35: =Ni*(J35-G35) -> 0.035435854 | P35: ='Fixing Money'!P35 -> 0.061811668 | Q35: =$C$33*Q34+T35 -> -0.17183388 | R35: =EXP(Q35) -> 0.84211905 | S35: =L35-L34 -> 0 | T35: -0.099798906
E36: 33 | F36: =F35+M35 -> 1.2569773 | G36: =G35+O35 -> 2000.5415 | H36: =$C$19*R36 -> 1637.4472 | I36: =LN(G36/H36) -> 0.20027946 | J36: =Beta0_1-Beta1*(L36-M36) -> 2001.0014 | K36: =F36*($B$11*G36-$B$12*M36) -> 1256.0589 | L36: =2 -> 2 | M36: =Mi*I36 -> 0.020027946 | N36: =L36-M36 -> 1.9799721 | O36: =Ni*(J36-G36) -> 0.045988555 | P36: ='Fixing Money'!P36 -> -0.0039967133 | Q36: =$C$33*Q35+T36 -> -0.20000874 | R36: =EXP(Q36) -> 0.81872359 | S36: =L36-L35 -> 0 | T36: -0.036766554
E37: 34 | F37: =F36+M36 -> 1.2770052 | G37: =G36+O36 -> 2000.5875 | H37: =$C$19*R37 -> 1689.5395 | I37: =LN(G37/H37) -> 0.16898486 | J37: =Beta0_1-Beta1*(L37-M37) -> 2000.8449 | K37: =F37*($B$11*G37-$B$12*M37) -> 1276.3014 | L37: =2 -> 2 | M37: =Mi*I37 -> 0.016898486 | N37: =L37-M37 -> 1.9831015 | O37: =Ni*(J37-G37) -> 0.025742399 | P37: ='Fixing Money'!P37 -> -0.11545842 | Q37: =$C$33*Q36+T37 -> -0.16869116 | R37: =EXP(Q37) -> 0.84476977 | S37: =L37-L36 -> 0 | T37: 0.021317151
E38: 35 | F38: =F37+M37 -> 1.2939037 | G38: =G37+O37 -> 2000.6132 | H38: =$C$19*R38 -> 1550.9428 | I38: =LN(G38/H38) -> 0.25459072 | J38: =Beta0_1-Beta1*(L38-M38) -> 2001.273 | K38: =F38*($B$11*G38-$B$12*M38) -> 1292.6534 | L38: =2 -> 2 | M38: =Mi*I38 -> 0.025459072 | N38: =L38-M38 -> 1.9745409 | O38: =Ni*(J38-G38) -> 0.06597109 | P38: ='Fixing Money'!P38 -> -0.073591785 | Q38: =$C$33*Q37+T38 -> -0.25428415 | R38: =EXP(Q38) -> 0.77547142 | S38: =L38-L37 -> 0 | T38: -0.094027551
E39: 36 | F39: =F38+M38 -> 1.3193628 | G39: =G38+O38 -> 2000.6792 | H39: =$C$19*R39 -> 1605.6034 | I39: =LN(G39/H39) -> 0.21998709 | J39: =Beta0_1-Beta1*(L39-M39) -> 2001.0999 | K39: =F39*($B$11*G39-$B$12*M39) -> 1318.3596 | L39: =2 -> 2 | M39: =Mi*I39 -> 0.021998709 | N39: =L39-M39 -> 1.9780013 | O39: =Ni*(J39-G39) -> 0.042072162 | P39: ='Fixing Money'!P39 -> -0.06729214 | Q39: =$C$33*Q38+T39 -> -0.21964754 | R39: =EXP(Q39) -> 0.80280171 | S39: =L39-L38 -> 0 | T39: 0.021922405
E40: 37 | F40: =F39+M39 -> 1.3413615 | G40: =G39+O39 -> 2000.7213 | H40: =$C$19*R40 -> 1519.98 | I40: =LN(G40/H40) -> 0.27481059 | J40: =Beta0_1-Beta1*(L40-M40) -> 2001.3741 | K40: =F40*($B$11*G40-$B$12*M40) -> 1340.0021 | L40: =2 -> 2 | M40: =Mi*I40 -> 0.027481059 | N40: =L40-M40 -> 1.9725189 | O40: =Ni*(J40-G40) -> 0.0652767 | P40: ='Fixing Money'!P40 -> -0.068782832 | Q40: =$C$33*Q39+T40 -> -0.27445002 | R40: =EXP(Q40) -> 0.75998999 | S40: =L40-L39 -> 0 | T40: -0.065784857
...

Sheet Base Prod with Taylor
A1: EXERCISE 2: Dynamic IS-LM model with a Recurring Productivity Shock and Money Instrument | T1: fixed ep
E2: Time | F2: p | G2: y | H2: yd | I2: yn | J2: GAP | K2: m | L2: i | M2: ∆p | N2: Real i | O2: ∆y | P2: epsilon | Q2: z | R2: Z | S2: ∆i | T2: epsilon
A3: Endogenous variables | B3: Change over time | E3: 0 | F3: =(Theta*Beta0_0)/Beta1+m_0-(Psi+Theta/Beta1)*ypot_0 -> 1 | G3: =ypot_0 -> 2000 | H3: =Beta0_0-Beta1*(L3-M3) -> 2000 | I3: 2000 | J3: =G3-I3 -> 0 | K3: =F3*($B$10*G3-$B$11*M3) -> 100 | L3: 2 | M3: =Mi*(G3-ypot_0) -> 0 | N3: =L3-M3 -> 2 | O3: =Ni*(H3-G3) -> 0 | P3: 0 | Q3: 0 | R3: 1 | S3: 0 | T3: 0
A4: p: Price level | B4: ∆p: Inflation | E4: 1 | F4: =F3+M3 -> 1 | G4: =G3+O3 -> 2000 | H4: =Beta0_1-Beta1*(L4-M4) -> 2000 | I4: =$B$19*R4 -> 2000 | J4: =LN(G4)-LN(I4) -> 0 | K4: =F4*($B$10*G4-$B$11*M4) -> 100 | L4: =$C$36*L3 + (1-$C$36)*(2 + $C$37 *J3 + $C$38 * M3) -> 2 | M4: =Mi*(J4) -> 0 | N4: =L4-M4 -> 2 | O4: =Ni*(H4-G4) -> 0 | P4: ='Fixing Money'!P4 -> 0 | Q4: =$C$33*Q3+T4 -> 0 | R4: =EXP(Q4) -> 1 | S4: =L4-L3 -> 0 | T4: 0
A5: y: Output | B5: ∆y: Output growth | E5: 2 | F5: =F4+M4 -> 1 | G5: =G4+O4 -> 2000 | H5: =Beta0_1-Beta1*(L5-M5) -> 2000.209 | I5: =$B$19*R5 -> 1918.1403 | J5: =LN(G5)-LN(I5) -> 0.041791046 | K5: =F5*($B$10*G5-$B$11*M5) -> 99.99791 | L5: =$C$36*L4 + (1-$C$36)*(2 + $C$37 *J4 + $C$38 * M4) -> 2 | M5: =Mi*(J5) -> 0.0041791046 | N5: =L5-M5 -> 1.9958209 | O5: =Ni*(H5-G5) -> 0.020895523 | P5: ='Fixing Money'!P5 -> -0.032427153 | Q5: =$C$33*Q4+T5 -> -0.041791046 | R5: =EXP(Q5) -> 0.95907016 | S5: =L5-L4 -> 0 | T5: -0.041791046
A6: yd: Aggregate demand | E6: 3 | F6: =F5+M5 -> 1.0041791 | G6: =G5+O5 -> 2000.0209 | H6: =Beta0_1-Beta1*(L6-M6) -> 1999.7993 | I6: =$B$19*R6 -> 1915.0047 | J6: =LN(G6)-LN(I6) -> 0.043437568 | K6: =F6*($B$10*G6-$B$11*M6) -> 100.41678 | L6: =$C$36*L5 + (1-$C$36)*(2 + $C$37 *J5 + $C$38 * M5) -> 2.0083582 | M6: =Mi*(J6) -> 0.0043437568 | N6: =L6-M6 -> 2.0040145 | O6: =Ni*(H6-G6) -> -0.022161814 | P6: ='Fixing Money'!P6 -> 0.063067809 | Q6: =$C$33*Q5+T6 -> -0.043427121 | R6: =EXP(Q6) -> 0.95750233 | S6: =L6-L5 -> 0.0083582092 | T6: -0.0037256268
A7: i: Nominal interest rate | E7: 4 | F7: =F6+M6 -> 1.0085229 | G7: =G6+O6 -> 1999.9987 | H7: =Beta0_1-Beta1*(L7-M7) -> 1999.9231 | I7: =$B$19*R7 -> 1861.9896 | J7: =LN(G7)-LN(I7) -> 0.071500974 | K7: =F7*($B$10*G7-$B$11*M7) -> 100.84862 | L7: =$C$36*L6 + (1-$C$36)*(2 + $C$37 *J6 + $C$38 * M6) -> 2.0086875 | M7: =Mi*(J7) -> 0.0071500974 | N7: =L7-M7 -> 2.0015374 | O7: =Ni*(H7-G7) -> -0.0075604523 | P7: ='Fixing Money'!P7 -> 0.17506394 | Q7: =$C$33*Q6+T7 -> -0.071501607 | R7: =EXP(Q7) -> 0.93099478 | S7: =L7-L6 -> 0.00032930444 | T7: -0.030245842
E8: 5 | F8: =F7+M7 -> 1.015673 | G8: =G7+O7 -> 1999.9912 | H8: =Beta0_1-Beta1*(L8-M8) -> 1999.5426 | I8: =$B$19*R8 -> 1899.5451 | J8: =LN(G8)-LN(I8) -> 0.051528325 | K8: =F8*($B$10*G8-$B$11*M8) -> 101.56423 | L8: =$C$36*L7 + (1-$C$36)*(2 + $C$37 *J7 + $C$38 * M7) -> 2.0143002 | M8: =Mi*(J8) -> 0.0051528325 | N8: =L8-M8 -> 2.0091474 | O8: =Ni*(H8-G8) -> -0.044854137 | P8: ='Fixing Money'!P8 -> -0.015373145 | Q8: =$C$33*Q7+T8 -> -0.051532739 | R8: =EXP(Q8) -> 0.94977256 | S8: =L8-L7 -> 0.0056126811 | T8: 0.016393788
A9: Parameters | E9: 6 | F9: =F8+M8 -> 1.0208258 | G9: =G8+O8 -> 1999.9463 | H9: =Beta0_1-Beta1*(L9-M9) -> 1999.9072 | I9: =$B$19*R9 -> 1837.9078 | J9: =LN(G9)-LN(I9) -> 0.084492458 | K9: =F9*($B$10*G9-$B$11*M9) -> 102.07553 | L9: =$C$36*L8 + (1-$C$36)*(2 + $C$37 *J8 + $C$38 * M8) -> 2.0103057 | M9: =Mi*(J9) -> 0.0084492458 | N9: =L9-M9 -> 2.0018564 | O9: =Ni*(H9-G9) -> -0.0039140082 | P9: ='Fixing Money'!P9 -> -0.039132545 | Q9: =$C$33*Q8+T9 -> -0.084519299 | R9: =EXP(Q9) -> 0.91895392 | S9: =L9-L8 -> -0.0039945297 | T9: -0.035563197
A10: Psi | B10: 0.05 | E10: 7 | F10: =F9+M9 -> 1.029275 | G10: =G9+O9 -> 1999.9424 | H10: =Beta0_1-Beta1*(L10-M10) -> 1999.3837 | I10: =$B$19*R10 -> 1910.5672 | J10: =LN(G10)-LN(I10) -> 0.045718217 | K10: =F10*($B$10*G10-$B$11*M10) -> 102.92219 | L10: =$C$36*L9 + (1-$C$36)*(2 + $C$37 *J9 + $C$38 * M9) -> 2.0168985 | M10: =Mi*(J10) -> 0.0045718217 | N10: =L10-M10 -> 2.0123267 | O10: =Ni*(H10-G10) -> -0.055873861 | P10: ='Fixing Money'!P10 -> -0.0063226409 | Q10: =$C$33*Q9+T10 -> -0.045747015 | R10: =EXP(Q10) -> 0.9552836 | S10: =L10-L9 -> 0.0065928266 | T10: 0.034546319
A11: Theta | B11: 0.5 | E11: 8 | F11: =F10+M10 -> 1.0338469 | G11: =G10+O10 -> 1999.8865 | H11: =Beta0_1-Beta1*(L11-M11) -> 1999.389 | I11: =$B$19*R11 -> 2062.3793 | J11: =LN(G11)-LN(I11) -> -0.03076985 | K11: =F11*($B$10*G11-$B$11*M11) -> 103.38041 | L11: =$C$36*L10 + (1-$C$36)*(2 + $C$37 *J10 + $C$38 * M10) -> 2.0091436 | M11: =Mi*(J11) -> -0.003076985 | N11: =L11-M11 -> 2.0122206 | O11: =Ni*(H11-G11) -> -0.049756268 | P11: ='Fixing Money'!P11 -> -0.022154893 | Q11: =$C$33*Q10+T11 -> 0.030713115 | R11: =EXP(Q11) -> 1.0311896 | S11: =L11-L10 -> -0.0077548482 | T11: 0.074172779
A12: Beta1 | B12: 50 | E12: 9 | F12: =F11+M11 -> 1.0307699 | G12: =G11+O11 -> 1999.8368 | H12: =Beta0_1-Beta1*(L12-M12) -> 1999.967 | I12: =$B$19*R12 -> 2140.8542 | J12: =LN(G12)-LN(I12) -> -0.068139366 | K12: =F12*($B$10*G12-$B$11*M12) -> 103.07209 | L12: =$C$36*L11 + (1-$C$36)*(2 + $C$37 *J11 + $C$38 * M11) -> 1.993846 | M12: =Mi*(J12) -> -0.0068139366 | N12: =L12-M12 -> 2.00066 | O12: =Ni*(H12-G12) -> 0.013022669 | P12: ='Fixing Money'!P12 -> 0.058675604 | Q12: =$C$33*Q11+T12 -> 0.06805775 | R12: =EXP(Q12) -> 1.0704271 | S12: =L12-L11 -> -0.015297614 | T12: 0.038880291
A13: Mi | B13: 0.1 | E13: 10 | F13: =F12+M12 -> 1.0239559 | G13: =G12+O12 -> 1999.8498 | H13: =Beta0_1-Beta1*(L13-M13) -> 2000.5965 | I13: =$B$19*R13 -> 2034.0884 | J13: =LN(G13)-LN(I13) -> -0.016975673 | K13: =F13*($B$10*G13-$B$11*M13) -> 102.38877 | L13: =$C$36*L12 + (1-$C$36)*(2 + $C$37 *J12 + $C$38 * M12) -> 1.9863721 | M13: =Mi*(J13) -> -0.0016975673 | N13: =L13-M13 -> 1.9880697 | O13: =Ni*(H13-G13) -> 0.074671764 | P13: ='Fixing Money'!P13 -> 0.11716061 | Q13: =$C$33*Q12+T13 -> 0.016900569 | R13: =EXP(Q13) -> 1.0170442 | S13: =L13-L12 -> -0.0074739031 | T13: -0.047754294
A14: Ni | B14: 0.1 | E14: 11 | F14: =F13+M13 -> 1.0222584 | G14: =G13+O13 -> 1999.9245 | H14: =Beta0_1-Beta1*(L14-M14) -> 2000.3873 | I14: =$B$19*R14 -> 1914.758 | J14: =LN(G14)-LN(I14) -> 0.04351819 | K14: =F14*($B$10*G14-$B$11*M14) -> 102.21975 | L14: =$C$36*L13 + (1-$C$36)*(2 + $C$37 *J13 + $C$38 * M13) -> 1.9966049 | M14: =Mi*(J14) -> 0.004351819 | N14: =L14-M14 -> 1.992253 | O14: =Ni*(H14-G14) -> 0.046287826 | P14: ='Fixing Money'!P14 -> 0.040820445 | Q14: =$C$33*Q13+T14 -> -0.043555956 | R14: =EXP(Q14) -> 0.95737898 | S14: =L14-L13 -> 0.010232739 | T14: -0.059611496
E15: 12 | F15: =F14+M14 -> 1.0266102 | G15: =G14+O14 -> 1999.9708 | H15: =Beta0_1-Beta1*(L15-M15) -> 2000.1119 | I15: =$B$19*R15 -> 1792.6735 | J15: =LN(G15)-LN(I15) -> 0.10942447 | K15: =F15*($B$10*G15-$B$11*M15) -> 102.6539 | L15: =$C$36*L14 + (1-$C$36)*(2 + $C$37 *J14 + $C$38 * M14) -> 2.0087036 | M15: =Mi*(J15) -> 0.010942447 | N15: =L15-M15 -> 1.9977612 | O15: =Ni*(H15-G15) -> 0.014118321 | P15: ='Fixing Money'!P15 -> 0.065941603 | Q15: =$C$33*Q14+T15 -> -0.10943909 | R15: =EXP(Q15) -> 0.89633676 | S15: =L15-L14 -> 0.012098773 | T15: -0.068060934
A16: Exogenous variables | B16: Initial value | C16: Final value | E16: 13 | F16: =F15+M15 -> 1.0375526 | G16: =G15+O15 -> 1999.9849 | H16: =Beta0_1-Beta1*(L16-M16) -> 1999.0043 | I16: =$B$19*R16 -> 1960.9371 | J16: =LN(G16)-LN(I16) -> 0.019717158 | K16: =F16*($B$10*G16-$B$11*M16) -> 103.75346 | L16: =$C$36*L15 + (1-$C$36)*(2 + $C$37 *J15 + $C$38 * M15) -> 2.0218849 | M16: =Mi*(J16) -> 0.0019717158 | N16: =L16-M16 -> 2.0199132 | O16: =Ni*(H16-G16) -> -0.098053448 | P16: ='Fixing Money'!P16 -> -0.08553997 | Q16: =$C$33*Q15+T16 -> -0.01972472 | R16: =EXP(Q16) -> 0.98046854 | S16: =L16-L15 -> 0.013181256 | T16: 0.084242417
A17: m: Money | B17: 100 | C17: 100 | E17: 14 | F17: =F16+M16 -> 1.0395244 | G17: =G16+O16 -> 1999.8868 | H17: =Beta0_1-Beta1*(L17-M17) -> 2000.3182 | I17: =$B$19*R17 -> 1804.0116 | J17: =LN(G17)-LN(I17) -> 0.10307774 | K17: =F17*($B$10*G17-$B$11*M17) -> 103.9412 | L17: =$C$36*L16 + (1-$C$36)*(2 + $C$37 *J16 + $C$38 * M16) -> 2.0039434 | M17: =Mi*(J17) -> 0.010307774 | N17: =L17-M17 -> 1.9936357 | O17: =Ni*(H17-G17) -> 0.043139501 | P17: ='Fixing Money'!P17 -> -0.025298068 | Q17: =$C$33*Q16+T17 -> -0.10313433 | R17: =EXP(Q17) -> 0.9020058 | S17: =L17-L16 -> -0.017941463 | T17: -0.084395848
A18: Beta0: Government spending | B18: 2100 | C18: 2100 | E18: 15 | F18: =F17+M17 -> 1.0498321 | G18: =G17+O17 -> 1999.93 | H18: =Beta0_1-Beta1*(L18-M18) -> 1999.5604 | I18: =$B$19*R18 -> 1776.9211 | J18: =LN(G18)-LN(I18) -> 0.11823 | K18: =F18*($B$10*G18-$B$11*M18) -> 104.97333 | L18: =$C$36*L17 + (1-$C$36)*(2 + $C$37 *J17 + $C$38 * M17) -> 2.0206155 | M18: =Mi*(J18) -> 0.011823 | N18: =L18-M18 -> 2.0087925 | O18: =Ni*(H18-G18) -> -0.036958902 | P18: ='Fixing Money'!P18 -> -0.011113111 | Q18: =$C$33*Q17+T18 -> -0.11826502 | R18: =EXP(Q18) -> 0.88846056 | S18: =L18-L17 -> 0.016672117 | T18: -0.020287407
A19: Ypot: Potential output | B19: 2000 | C19: 2000 | E19: 16 | F19: =F18+M18 -> 1.0616551 | G19: =G18+O18 -> 1999.893 | H19: =Beta0_1-Beta1*(L19-M19) -> 1999.4262 | I19: =$B$19*R19 -> 1770.7316 | J19: =LN(G19)-LN(I19) -> 0.12170087 | K19: =F19*($B$10*G19-$B$11*M19) -> 106.15337 | L19: =$C$36*L18 + (1-$C$36)*(2 + $C$37 *J18 + $C$38 * M18) -> 2.023646 | M19: =Mi*(J19) -> 0.012170087 | N19: =L19-M19 -> 2.0114759 | O19: =Ni*(H19-G19) -> -0.046679842 | P19: ='Fixing Money'!P19 -> 0.060955149 | Q19: =$C$33*Q18+T19 -> -0.12175437 | R19: =EXP(Q19) -> 0.88536582 | S19: =L19-L18 -> 0.0030304522 | T19: -0.0094025934
E20: 17 | F20: =F19+M19 -> 1.0738252 | G20: =G19+O19 -> 1999.8463 | H20: =Beta0_1-Beta1*(L20-M20) -> 1999.4132 | I20: =$B$19*R20 -> 1763.0348 | J20: =LN(G20)-LN(I20) -> 0.12603367 | K20: =F20*($B$10*G20-$B$11*M20) -> 107.3675 | L20: =$C$36*L19 + (1-$C$36)*(2 + $C$37 *J19 + $C$38 * M19) -> 2.0243402 | M20: =Mi*(J20) -> 0.012603367 | N20: =L20-M20 -> 2.0117368 | O20: =Ni*(H20-G20) -> -0.043316317 | P20: ='Fixing Money'!P20 -> -0.034670115 | Q20: =$C$33*Q19+T20 -> -0.12611051 | R20: =EXP(Q20) -> 0.88151742 | S20: =L20-L19 -> 0.00069417239 | T20: -0.010443865
A21: Steady State | B21: Initial SS | C21: Final SS | E21: 18 | F21: =F20+M20 -> 1.0864286 | G21: =G20+O20 -> 1999.803 | H21: =Beta0_1-Beta1*(L21-M21) -> 1999.0697 | I21: =$B$19*R21 -> 1872.0644 | J21: =LN(G21)-LN(I21) -> 0.066006906 | K21: =F21*($B$10*G21-$B$11*M21) -> 108.62857 | L21: =$C$36*L20 + (1-$C$36)*(2 + $C$37 *J20 + $C$38 * M20) -> 2.0252067 | M21: =Mi*(J21) -> 0.0066006906 | N21: =L21-M21 -> 2.018606 | O21: =Ni*(H21-G21) -> -0.073330872 | P21: ='Fixing Money'!P21 -> -0.010745592 | Q21: =$C$33*Q20+T21 -> -0.066105408 | R21: =EXP(Q21) -> 0.93603219 | S21: =L21-L20 -> 0.00086656099 | T21: 0.053699578
A22: Steady state for p | B22: =(Theta*Beta0_0)/Beta1+m_0-(Psi+Theta/Beta1)*ybar0 -> 1 | C22: =(Theta*Beta0_1)/Beta1+m_1-(Psi+Theta/Beta1)*ybar1 -> 1 | E22: 19 | F22: =F21+M21 -> 1.0930293 | G22: =G21+O21 -> 1999.7297 | H22: =Beta0_1-Beta1*(L22-M22) -> 1999.6209 | I22: =$B$19*R22 -> 1890.4639 | J22: =LN(G22)-LN(I22) -> 0.056189766 | K22: =F22*($B$10*G22-$B$11*M22) -> 109.28508 | L22: =$C$36*L21 + (1-$C$36)*(2 + $C$37 *J21 + $C$38 * M21) -> 2.0132014 | M22: =Mi*(J22) -> 0.0056189766 | N22: =L22-M22 -> 2.0075824 | O22: =Ni*(H22-G22) -> -0.010879592 | P22: ='Fixing Money'!P22 -> -0.03327487 | Q22: =$C$33*Q21+T22 -> -0.056324937 | R22: =EXP(Q22) -> 0.94523195 | S22: =L22-L21 -> -0.012005353 | T22: 0.0064752007
A23: Steady state for y | B23: =ypot0 -> 2000 | C23: =ypot1 -> 2000 | E23: 20 | F23: =F22+M22 -> 1.0986482 | G23: =G22+O22 -> 1999.7188 | H23: =Beta0_1-Beta1*(L23-M23) -> 1999.4826 | I23: =$B$19*R23 -> 1981.9893 | J23: =LN(G23)-LN(I23) -> 0.0089055322 | K23: =F23*($B$10*G23-$B$11*M23) -> 109.84889 | L23: =$C$36*L22 + (1-$C$36)*(2 + $C$37 *J22 + $C$38 * M22) -> 2.011238 | M23: =Mi*(J23) -> 0.00089055322 | N23: =L23-M23 -> 2.0103474 | O23: =Ni*(H23-G23) -> -0.023616609 | P23: ='Fixing Money'!P23 -> 0.04242673 | Q23: =$C$33*Q22+T23 -> -0.009046144 | R23: =EXP(Q23) -> 0.99099465 | S23: =L23-L22 -> -0.0019634282 | T23: 0.044462546
E24: 21 | F24: =F23+M23 -> 1.0995388 | G24: =G23+O23 -> 1999.6952 | H24: =Beta0_1-Beta1*(L24-M24) -> 2000.237 | I24: =$B$19*R24 -> 1873.4658 | J24: =LN(G24)-LN(I24) -> 0.065204668 | K24: =F24*($B$10*G24-$B$11*M24) -> 109.93354 | L24: =$C$36*L23 + (1-$C$36)*(2 + $C$37 *J23 + $C$38 * M23) -> 2.0017811 | M24: =Mi*(J24) -> 0.0065204668 | N24: =L24-M24 -> 1.9952606 | O24: =Ni*(H24-G24) -> 0.054178853 | P24: ='Fixing Money'!P24 -> 0.097560915 | Q24: =$C$33*Q23+T24 -> -0.06535709 | R24: =EXP(Q24) -> 0.93673291 | S24: =L24-L23 -> -0.0094568467 | T24: -0.056763253
A25: Eigenvalues | B25: Real | C25: Imaginary | E25: 22 | F25: =F24+M24 -> 1.1060593 | G25: =G24+O24 -> 1999.7494 | H25: =Beta0_1-Beta1*(L25-M25) -> 1999.7994 | I25: =$B$19*R25 -> 1827.1103 | J25: =LN(G25)-LN(I25) -> 0.090286181 | K25: =F25*($B$10*G25-$B$11*M25) -> 110.58707 | L25: =$C$36*L24 + (1-$C$36)*(2 + $C$37 *J24 + $C$38 * M24) -> 2.0130409 | M25: =Mi*(J25) -> 0.0090286181 | N25: =L25-M25 -> 2.0040123 | O25: =Ni*(H25-G25) -> 0.0050025893 | P25: ='Fixing Money'!P25 -> -0.043523728 | Q25: =$C$33*Q24+T25 -> -0.09041151 | R25: =EXP(Q25) -> 0.91355517 | S25: =L25-L24 -> 0.011259827 | T25: -0.028322275
A26: λ1 | B26: =IF((Ni*(Beta1*Mi-((Beta1*Psi)/Theta)-1))^2-4*(Ni*Beta1*Mi)/Theta>0,(Ni*(Beta1*Mi-((Beta1*Psi)/Theta)-1)+SQRT((Ni*(Beta1*Mi-((Beta1*Psi)/Theta)-1))^2-4*(Ni*Beta1*Mi)/Theta))/2,((Ni*(Beta1*Mi-((Beta1*Psi)/Theta)-1))/2)) -> -0.05 | C26: =IF((Ni*((Beta1*Mi-(Beta1*Psi)/Theta)-1)^2-4*(Ni*Beta1*Mi)/Theta)>0, 0, +SQRT(-(Ni*((Beta1*Mi-(Beta1*Psi)/Theta)-1)^2-4*(Ni*Beta1*Mi)/Theta))/2) -> 0.98742088 | E26: 23 | F26: =F25+M25 -> 1.1150879 | G26: =G25+O25 -> 1999.7544 | H26: =Beta0_1-Beta1*(L26-M26) -> 1999.63 | I26: =$B$19*R26 -> 1797.617 | J26: =LN(G26)-LN(I26) -> 0.10656243 | K26: =F26*($B$10*G26-$B$11*M26) -> 111.48915 | L26: =$C$36*L25 + (1-$C$36)*(2 + $C$37 *J25 + $C$38 * M25) -> 2.0180572 | M26: =Mi*(J26) -> 0.010656243 | N26: =L26-M26 -> 2.007401 | O26: =Ni*(H26-G26) -> -0.012441058 | P26: ='Fixing Money'!P26 -> -0.028108665 | Q26: =$C$33*Q25+T26 -> -0.10668526 | R26: =EXP(Q26) -> 0.89880852 | S26: =L26-L25 -> 0.0050163027 | T26: -0.020794324
A27: λ2 | B27: =IF((Ni*(Beta1*Mi-((Beta1*Psi)/Theta)-1))^2-4*(Ni*Beta1*Mi)/Theta>0,(Ni*(Beta1*Mi-((Beta1*Psi)/Theta)-1)-SQRT((Ni*(Beta1*Mi-((Beta1*Psi)/Theta)-1))^2-4*(Ni*Beta1*Mi)/Theta))/2,((Ni*(Beta1*Mi-((Beta1*Psi)/Theta)-1))/2)) -> -0.05 | C27: =IF((Ni*((Beta1*Mi-(Beta1*Psi)/Theta)-1)^2-4*(Ni*Beta1*Mi)/Theta)>0, 0, -SQRT(-(Ni*((Beta1*Mi-(Beta1*Psi)/Theta)-1)^2-4*(Ni*Beta1*Mi)/Theta))/2) -> -0.98742088 | E27: 24 | F27: =F26+M26 -> 1.1257441 | G27: =G26+O26 -> 1999.7419 | H27: =Beta0_1-Beta1*(L27-M27) -> 1999.9307 | I27: =$B$19*R27 -> 1638.4452 | J27: =LN(G27)-LN(I27) -> 0.19927037 | K27: =F27*($B$10*G27-$B$11*M27) -> 112.54867 | L27: =$C$36*L26 + (1-$C$36)*(2 + $C$37 *J26 + $C$38 * M26) -> 2.0213125 | M27: =Mi*(J27) -> 0.019927037 | N27: =L27-M27 -> 2.0013854 | O27: =Ni*(H27-G27) -> 0.018880768 | P27: ='Fixing Money'!P27 -> -0.048638078 | Q27: =$C$33*Q26+T27 -> -0.19939942 | R27: =EXP(Q27) -> 0.81922261 | S27: =L27-L26 -> 0.00325525 | T27: -0.098048424
