Workbook
Name Alpha: 'Fixing Money'!#REF!
Name Beta: 'Fixing Money'!$B$9
Name Beta0_0: 'Fixing Money'!$B$18
Name Beta0_1: 'Fixing Money'!$C$18
Name Beta1: 'Fixing Money'!$B$12
Name Delta: 'Fixing Money'!$B$11
Name m_0: 'Fixing Money'!$B$17
Name m_1: 'Fixing Money'!$C$17
Name Mi: 'Fixing Money'!$B$13
Name Ni: 'Fixing Money'!$B$14
Name pbar_0: 'Fixing Money'!$B$22
Name pbar_1: 'Fixing Money'!$C$22
Name Psi: 'Fixing Money'!$B$10
Name Theta: 'Fixing Money'!$B$11
Name ybar0: 'Fixing Money'!$B$23
Name ybar1: 'Fixing Money'!$C$23
Name ypot_0: 'Fixing Money'!$B$19
Name ypot_1: 'Fixing Money'!$C$19
Name ypot0: 'Fixing Money'!$B$19
Name ypot1: 'Fixing Money'!$C$19

Sheet Fixing Money
A1: EXERCISE 2: Dynamic IS-LM model with a Recurring Productivity Shock: Fixing Money and Adjusting Interest Rates
E2: Time | F2: p | G2: y | H2: yd | I2: yn | J2: Gap | K2: m | L2: i | M2: ∆p | N2: Real i | O2: ∆y | P2: epsilon | Q2: z | R2: Z
A3: Endogenous variables | B3: Change over time | E3: 0 | F3: =(Theta*Beta0_0)/Beta1+m_0-(Psi+Theta/Beta1)*ypot_0 -> 1 | G3: =ypot_0 -> 2000 | H3: =Beta0_0 -Beta1*(L3-M3) -> 2000 | I3: =ypot_0*R3 -> 2000 | J3: =LN(G3/I3) -> 0 | K3: =100 -> 100 | L3: =-1/Theta*(m_0-F3-Psi*G3) -> 2 | M3: =Mi*J3 -> 0 | N3: =L3-M3 -> 2 | O3: =Ni*(H3-G3) -> 1.3642421e-13 | P3: 0 | Q3: 0 | R3: 1
A4: p: Price level | B4: ∆p: Inflation | E4: 1 | F4: =F3+M3 -> 1 | G4: =G3+O3 -> 2000 | H4: =Beta0_0 -Beta1*(L4-M4) -> 2000 | I4: =ypot_0*R4 -> 2000 | J4: =LN(G4/I4) -> 2.220446e-16 | K4: =100 -> 100 | L4: =-1/Theta*(m_0-F4-Psi*G4) -> 2 | M4: =Mi*LN(G4/(I4)) -> 2.220446e-17 | N4: =L4-M4 -> 2 | O4: =Ni*(H4-G4) -> -2.2737368e-14 | P4: 0 | Q4: =$C$33*Q3+P4 -> 0 | R4: =EXP(Q4) -> 1
A5: y: Output | B5: ∆y: Output growth | E5: 2 | F5: =F4+M4 -> 1 | G5: =G4+O4 -> 2000 | H5: =Beta0_0 -Beta1*(L5-M5) -> 2000.1136 | I5: =ypot_0*R5 -> 1955.0693 | J5: =LN(G5/I5) -> 0.022721528 | K5: =100 -> 100 | L5: =-1/Theta*(m_0-F5-Psi*G5) -> 2 | M5: =Mi*LN(G5/(I5)) -> 0.0022721528 | N5: =L5-M5 -> 1.9977278 | O5: =Ni*(H5-G5) -> 0.011360764 | P5: -0.022721528 | Q5: =$C$33*Q4+P5 -> -0.022721528 | R5: =EXP(Q5) -> 0.97753466
A6: yd: Aggregate demand | E6: 3 | F6: =F5+M5 -> 1.0022722 | G6: =G5+O5 -> 2000.0114 | H6: =Beta0_0 -Beta1*(L6-M6) -> 1999.9101 | I6: =ypot_0*R6 -> 1923.8419 | J6: =LN(G6/I6) -> 0.038828687 | K6: =100 -> 100 | L6: =-1/Theta*(m_0-F6-Psi*G6) -> 2.0056804 | M6: =Mi*LN(G6/(I6)) -> 0.0038828687 | N6: =L6-M6 -> 2.0017975 | O6: =Ni*(H6-G6) -> -0.010123643 | P6: -0.018373631 | Q6: =$C$33*Q5+P6 -> -0.038823007 | R6: =EXP(Q6) -> 0.96192095
A7: i: Nominal interest rate | E7: 4 | F7: =F6+M6 -> 1.006155 | G7: =G6+O6 -> 2000.0012 | H7: =Beta0_0 -Beta1*(L7-M7) -> 1999.3787 | I7: =ypot_0*R7 -> 1999.8303 | J7: =LN(G7/I7) -> 8.5487441e-05 | K7: =100 -> 100 | L7: =-1/Theta*(m_0-F7-Psi*G7) -> 2.0124338 | M7: =Mi*LN(G7/(I7)) -> 8.5487441e-06 | N7: =L7-M7 -> 2.0124252 | O7: =Ni*(H7-G7) -> -0.062249744 | P7: 0.034855837 | Q7: =$C$33*Q6+P7 -> -8.4868881e-05 | R7: =EXP(Q7) -> 0.99991513
E8: 5 | F8: =F7+M7 -> 1.0061636 | G8: =G7+O7 -> 1999.939 | H8: =Beta0_0 -Beta1*(L8-M8) -> 1999.3888 | I8: =ypot_0*R8 -> 2123.5825 | J8: =LN(G8/I8) -> -0.059987841 | K8: =100 -> 100 | L8: =-1/Theta*(m_0-F8-Psi*G8) -> 2.0062259 | M8: =Mi*LN(G8/(I8)) -> -0.0059987841 | N8: =L8-M8 -> 2.0122247 | O8: =Ni*(H8-G8) -> -0.055022049 | P8: 0.060033716 | Q8: =$C$33*Q7+P8 -> 0.059957334 | R8: =EXP(Q8) -> 1.0617912
A9: Parameters | E9: 6 | F9: =F8+M8 -> 1.0001648 | G9: =G8+O8 -> 1999.884 | H9: =Beta0_0 -Beta1*(L9-M9) -> 1999.8729 | I9: =ypot_0*R9 -> 2296.1688 | J9: =LN(G9/I9) -> -0.13815285 | K9: =100 -> 100 | L9: =-1/Theta*(m_0-F9-Psi*G9) -> 1.9887261 | M9: =Mi*LN(G9/(I9)) -> -0.013815285 | N9: =L9-M9 -> 2.0025414 | O9: =Ni*(H9-G9) -> -0.0011034816 | P9: 0.084133227 | Q9: =$C$33*Q8+P9 -> 0.13809483 | R9: =EXP(Q9) -> 1.1480844
A10: Psi | B10: 0.05 | E10: 7 | F10: =F9+M9 -> 0.9863495 | G10: =G9+O9 -> 1999.8829 | H10: =Beta0_0 -Beta1*(L10-M10) -> 2001.5492 | I10: =ypot_0*R10 -> 2167.1253 | J10: =LN(G10/I10) -> -0.080312919 | K10: =100 -> 100 | L10: =-1/Theta*(m_0-F10-Psi*G10) -> 1.9609852 | M10: =Mi*LN(G10/(I10)) -> -0.0080312919 | N10: =L10-M10 -> 1.9690165 | O10: =Ni*(H10-G10) -> 0.16663142 | P10: -0.044030997 | Q10: =$C$33*Q9+P10 -> 0.080254348 | R10: =EXP(Q10) -> 1.0835626
A11: Theta | B11: 0.5 | E11: 8 | F11: =F10+M10 -> 0.97831821 | G11: =G10+O10 -> 2000.0495 | H11: =Beta0_0 -Beta1*(L11-M11) -> 2001.3359 | I11: =ypot_0*R11 -> 2248.211 | J11: =LN(G11/I11) -> -0.11696286 | K11: =100 -> 100 | L11: =-1/Theta*(m_0-F11-Psi*G11) -> 1.9615857 | M11: =Mi*LN(G11/(I11)) -> -0.011696286 | N11: =L11-M11 -> 1.973282 | O11: =Ni*(H11-G11) -> 0.12864052 | P11: 0.044758691 | Q11: =$C$33*Q10+P11 -> 0.1169876 | R11: =EXP(Q11) -> 1.1241055
A12: Beta1 | B12: 50 | E12: 9 | F12: =F11+M11 -> 0.96662192 | G12: =G11+O11 -> 2000.1781 | H12: =Beta0_0 -Beta1*(L12-M12) -> 2001.8331 | I12: =ypot_0*R12 -> 2261.5438 | J12: =LN(G12/I12) -> -0.12281145 | K12: =100 -> 100 | L12: =-1/Theta*(m_0-F12-Psi*G12) -> 1.9510572 | M12: =Mi*LN(G12/(I12)) -> -0.012281145 | N12: =L12-M12 -> 1.9633384 | O12: =Ni*(H12-G12) -> 0.16549477 | P12: 0.017611674 | Q12: =$C$33*Q11+P12 -> 0.12290052 | R12: =EXP(Q12) -> 1.1307719
A13: Mi | B13: 0.1 | E13: 10 | F13: =F12+M12 -> 0.95434078 | G13: =G12+O12 -> 2000.3436 | H13: =Beta0_0 -Beta1*(L13-M13) -> 2002.5382 | I13: =ypot_0*R13 -> 2128.1319 | J13: =LN(G13/I13) -> -0.061925578 | K13: =100 -> 100 | L13: =-1/Theta*(m_0-F13-Psi*G13) -> 1.9430444 | M13: =Mi*LN(G13/(I13)) -> -0.0061925578 | N13: =L13-M13 -> 1.949237 | O13: =Ni*(H13-G13) -> 0.2194523 | P13: -0.048513088 | Q13: =$C$33*Q12+P13 -> 0.062097378 | R13: =EXP(Q13) -> 1.064066
A14: Ni | B14: 0.1 | E14: 11 | F14: =F13+M13 -> 0.94814822 | G14: =G13+O13 -> 2000.5631 | H14: =Beta0_0 -Beta1*(L14-M14) -> 2001.9774 | I14: =ypot_0*R14 -> 2163.8752 | J14: =LN(G14/I14) -> -0.078472005 | K14: =100 -> 100 | L14: =-1/Theta*(m_0-F14-Psi*G14) -> 1.9526045 | M14: =Mi*LN(G14/(I14)) -> -0.0078472005 | N14: =L14-M14 -> 1.9604517 | O14: =Ni*(H14-G14) -> 0.14143328 | P14: 0.022865866 | Q14: =$C$33*Q13+P14 -> 0.078753506 | R14: =EXP(Q14) -> 1.0819376
E15: 12 | F15: =F14+M14 -> 0.94030102 | G15: =G14+O14 -> 2000.7045 | H15: =Beta0_0 -Beta1*(L15-M15) -> 2002.5237 | I15: =ypot_0*R15 -> 1970.3835 | J15: =LN(G15/I15) -> 0.015271202 | K15: =100 -> 100 | L15: =-1/Theta*(m_0-F15-Psi*G15) -> 1.9510535 | M15: =Mi*LN(G15/(I15)) -> 0.0015271202 | N15: =L15-M15 -> 1.9495263 | O15: =Ni*(H15-G15) -> 0.18191692 | P15: -0.085797162 | Q15: =$C$33*Q14+P15 -> -0.014919007 | R15: =EXP(Q15) -> 0.98519173
A16: Exogenous variables | B16: Initial value | C16: Final value | E16: 13 | F16: =F15+M15 -> 0.94182814 | G16: =G15+O15 -> 2000.8864 | H16: =Beta0_0 -Beta1*(L16-M16) -> 2001.6062 | I16: =ypot_0*R16 -> 1914.2996 | J16: =LN(G16/I16) -> 0.044238503 | K16: =100 -> 100 | L16: =-1/Theta*(m_0-F16-Psi*G16) -> 1.9722994 | M16: =Mi*LN(G16/(I16)) -> 0.0044238503 | N16: =L16-M16 -> 1.9678755 | O16: =Ni*(H16-G16) -> 0.071979218 | P16: -0.03036828 | Q16: =$C$33*Q15+P16 -> -0.043795386 | R16: =EXP(Q16) -> 0.95714978
A17: m: Money | B17: 100 | C17: 100 | E17: 14 | F17: =F16+M16 -> 0.94625199 | G17: =G16+O16 -> 2000.9584 | H17: =Beta0_0 -Beta1*(L17-M17) -> 2000.7678 | I17: =ypot_0*R17 -> 1928.266 | J17: =LN(G17/I17) -> 0.03700513 | K17: =100 -> 100 | L17: =-1/Theta*(m_0-F17-Psi*G17) -> 1.988345 | M17: =Mi*LN(G17/(I17)) -> 0.003700513 | N17: =L17-M17 -> 1.9846445 | O17: =Ni*(H17-G17) -> -0.019063502 | P17: 0.0028898073 | Q17: =$C$33*Q16+P17 -> -0.03652604 | R17: =EXP(Q17) -> 0.96413299
A18: Beta0: Government spending | B18: 2100 | C18: 2100 | E18: 15 | F18: =F17+M17 -> 0.9499525 | G18: =G17+O17 -> 2000.9393 | H18: =Beta0_0 -Beta1*(L18-M18) -> 2000.3567 | I18: =ypot_0*R18 -> 1981.5586 | J18: =LN(G18/I18) -> 0.0097330522 | K18: =100 -> 100 | L18: =-1/Theta*(m_0-F18-Psi*G18) -> 1.9938397 | M18: =Mi*LN(G18/(I18)) -> 0.00097330522 | N18: =L18-M18 -> 1.9928664 | O18: =Ni*(H18-G18) -> -0.058266571 | P18: 0.023609947 | Q18: =$C$33*Q17+P18 -> -0.0092634891 | R18: =EXP(Q18) -> 0.99077928
A19: Ypot: Potential output | B19: 2000 | C19: 2000 | E19: 16 | F19: =F18+M18 -> 0.95092581 | G19: =G18+O18 -> 2000.8811 | H19: =Beta0_0 -Beta1*(L19-M19) -> 2000.3229 | I19: =ypot_0*R19 -> 2073.8458 | J19: =LN(G19/I19) -> -0.035817132 | K19: =100 -> 100 | L19: =-1/Theta*(m_0-F19-Psi*G19) -> 1.9899596 | M19: =Mi*LN(G19/(I19)) -> -0.0035817132 | N19: =L19-M19 -> 1.9935414 | O19: =Ni*(H19-G19) -> -0.055814773 | P19: 0.044594715 | Q19: =$C$33*Q18+P19 -> 0.036257575 | R19: =EXP(Q19) -> 1.0369229
E20: 17 | F20: =F19+M19 -> 0.9473441 | G20: =G19+O19 -> 2000.8253 | H20: =Beta0_0 -Beta1*(L20-M20) -> 2000.401 | I20: =ypot_0*R20 -> 2319.1784 | J20: =LN(G20/I20) -> -0.14765327 | K20: =100 -> 100 | L20: =-1/Theta*(m_0-F20-Psi*G20) -> 1.9772147 | M20: =Mi*LN(G20/(I20)) -> -0.014765327 | N20: =L20-M20 -> 1.9919801 | O20: =Ni*(H20-G20) -> -0.042426847 | P20: 0.115434 | Q20: =$C$33*Q19+P20 -> 0.14806582 | R20: =EXP(Q20) -> 1.1595892
A21: Steady State | B21: Initial SS | C21: Final SS | E21: 18 | F21: =F20+M20 -> 0.93257877 | G21: =G20+O20 -> 2000.7828 | H21: =Beta0_0 -Beta1*(L21-M21) -> 2002.2497 | I21: =ypot_0*R21 -> 2246.0826 | J21: =LN(G21/I21) -> -0.11564909 | K21: =100 -> 100 | L21: =-1/Theta*(m_0-F21-Psi*G21) -> 1.9434414 | M21: =Mi*LN(G21/(I21)) -> -0.011564909 | N21: =L21-M21 -> 1.9550063 | O21: =Ni*(H21-G21) -> 0.14668462 | P21: -0.017218807 | Q21: =$C$33*Q20+P21 -> 0.11604043 | R21: =EXP(Q21) -> 1.1230413
A22: Steady state for p | B22: =(Theta*Beta0_0)/Beta1+m_0-(Psi+Theta/Beta1)*ybar0 -> 1 | C22: =(Theta*Beta0_1)/Beta1+m_1-(Psi+Theta/Beta1)*ybar1 -> 1 | E22: 19 | F22: =F21+M21 -> 0.92101386 | G22: =G21+O21 -> 2000.9295 | H22: =Beta0_0 -Beta1*(L22-M22) -> 2003.0275 | I22: =ypot_0*R22 -> 2092.3829 | J22: =LN(G22/I22) -> -0.044691749 | K22: =100 -> 100 | L22: =-1/Theta*(m_0-F22-Psi*G22) -> 1.93498 | M22: =Mi*LN(G22/(I22)) -> -0.0044691749 | N22: =L22-M22 -> 1.9394492 | O22: =Ni*(H22-G22) -> 0.20980161 | P22: -0.059279985 | Q22: =$C$33*Q21+P22 -> 0.045156403 | R22: =EXP(Q22) -> 1.0461915
A23: Steady state for y | B23: =ypot0 -> 2000 | C23: =ypot1 -> 2000 | E23: 20 | F23: =F22+M22 -> 0.91654468 | G23: =G22+O22 -> 2001.1393 | H23: =Beta0_0 -Beta1*(L23-M23) -> 2002.4182 | I23: =ypot_0*R23 -> 2095.6482 | J23: =LN(G23/I23) -> -0.046146221 | K23: =100 -> 100 | L23: =-1/Theta*(m_0-F23-Psi*G23) -> 1.9470219 | M23: =Mi*LN(G23/(I23)) -> -0.0046146221 | N23: =L23-M23 -> 1.9516365 | O23: =Ni*(H23-G23) -> 0.12788516 | P23: 0.0060749586 | Q23: =$C$33*Q22+P23 -> 0.046715721 | R23: =EXP(Q23) -> 1.0478241
E24: 21 | F24: =F23+M23 -> 0.91193006 | G24: =G23+O23 -> 2001.2672 | H24: =Beta0_0 -Beta1*(L24-M24) -> 2002.4422 | I24: =ypot_0*R24 -> 2012.7874 | J24: =LN(G24/I24) -> -0.0057399502 | K24: =100 -> 100 | L24: =-1/Theta*(m_0-F24-Psi*G24) -> 1.9505811 | M24: =Mi*LN(G24/(I24)) -> -0.00057399502 | N24: =L24-M24 -> 1.9511551 | O24: =Ni*(H24-G24) -> 0.11750342 | P24: -0.035670794 | Q24: =$C$33*Q23+P24 -> 0.0063733546 | R24: =EXP(Q24) -> 1.0063937
A25: Eigenvalues | B25: Real | C25: Imaginary | E25: 22 | F25: =F24+M24 -> 0.91135607 | G25: =G24+O24 -> 2001.3847 | H25: =Beta0_0 -Beta1*(L25-M25) -> 2001.9961 | I25: =ypot_0*R25 -> 1979.3853 | J25: =LN(G25/I25) -> 0.011052961 | K25: =100 -> 100 | L25: =-1/Theta*(m_0-F25-Psi*G25) -> 1.9611835 | M25: =Mi*LN(G25/(I25)) -> 0.0011052961 | N25: =L25-M25 -> 1.9600782 | O25: =Ni*(H25-G25) -> 0.061137773 | P25: -0.016096863 | Q25: =$C$33*Q24+P25 -> -0.010360843 | R25: =EXP(Q25) -> 0.98969265
A26: λ1 | B26: =IF((Ni*(Beta1*Mi-((Beta1*Psi)/Theta)-1))^2-4*(Ni*Beta1*Mi)/Theta>0,(Ni*(Beta1*Mi-((Beta1*Psi)/Theta)-1)+SQRT((Ni*(Beta1*Mi-((Beta1*Psi)/Theta)-1))^2-4*(Ni*Beta1*Mi)/Theta))/2,((Ni*(Beta1*Mi-((Beta1*Psi)/Theta)-1))/2)) -> -0.05 | C26: =IF((Ni*((Beta1*Mi-(Beta1*Psi)/Theta)-1)^2-4*(Ni*Beta1*Mi)/Theta)>0, 0, +SQRT(-(Ni*((Beta1*Mi-(Beta1*Psi)/Theta)-1)^2-4*(Ni*Beta1*Mi)/Theta))/2) -> 0.98742088 | E26: 23 | F26: =F25+M25 -> 0.91246136 | G26: =G25+O25 -> 2001.4459 | H26: =Beta0_0 -Beta1*(L26-M26) -> 2001.6962 | I26: =ypot_0*R26 -> 1933.9089 | J26: =LN(G26/I26) -> 0.034326574 | K26: =100 -> 100 | L26: =-1/Theta*(m_0-F26-Psi*G26) -> 1.9695078 | M26: =Mi*LN(G26/(I26)) -> 0.0034326574 | N26: =L26-M26 -> 1.9660752 | O26: =Ni*(H26-G26) -> 0.025038955 | P26: -0.02427915 | Q26: =$C$33*Q25+P26 -> -0.03360391 | R26: =EXP(Q26) -> 0.96695443
A27: λ2 | B27: =IF((Ni*(Beta1*Mi-((Beta1*Psi)/Theta)-1))^2-4*(Ni*Beta1*Mi)/Theta>0,(Ni*(Beta1*Mi-((Beta1*Psi)/Theta)-1)-SQRT((Ni*(Beta1*Mi-((Beta1*Psi)/Theta)-1))^2-4*(Ni*Beta1*Mi)/Theta))/2,((Ni*(Beta1*Mi-((Beta1*Psi)/Theta)-1))/2)) -> -0.05 | C27: =IF((Ni*((Beta1*Mi-(Beta1*Psi)/Theta)-1)^2-4*(Ni*Beta1*Mi)/Theta)>0, 0, -SQRT(-(Ni*((Beta1*Mi-(Beta1*Psi)/Theta)-1)^2-4*(Ni*Beta1*Mi)/Theta))/2) -> -0.98742088 | E27: 24 | F27: =F26+M26 -> 0.91589402 | G27: =G26+O26 -> 2001.4709 | H27: =Beta0_0 -Beta1*(L27-M27) -> 2001.1279 | I27: =ypot_0*R27 -> 1972.9516 | J27: =LN(G27/I27) -> 0.014351679 | K27: =100 -> 100 | L27: =-1/Theta*(m_0-F27-Psi*G27) -> 1.9788771 | M27: =Mi*LN(G27/(I27)) -> 0.0014351679 | N27: =L27-M27 -> 1.9774419 | O27: =Ni*(H27-G27) -> -0.034298439 | P27: 0.016627014 | Q27: =$C$33*Q26+P27 -> -0.013616504 | R27: =EXP(Q27) -> 0.98647578
E28: 25 | F28: =F27+M27 -> 0.91732919 | G28: =G27+O27 -> 2001.4366 | H28: =Beta0_0 -Beta1*(L28-M28) -> 2001.1276 | I28: =ypot_0*R28 -> 1984.0979 | J28: =LN(G28/I28) -> 0.0087008733 | K28: =100 -> 100 | L28: =-1/Theta*(m_0-F28-Psi*G28) -> 1.9783175 | M28: =Mi*LN(G28/(I28)) -> 0.00087008733 | N28: =L28-M28 -> 1.9774475 | O28: =Ni*(H28-G28) -> -0.030896457 | P28: 0.0042720185 | Q28: =$C$33*Q27+P28 -> -0.0079828353 | R28: =EXP(Q28) -> 0.99204894
A29: Stability condition | E29: 26 | F29: =F28+M28 -> 0.91819928 | G29: =G28+O28 -> 2001.4057 | H29: =Beta0_0 -Beta1*(L29-M29) -> 2001.101 | I29: =ypot_0*R29 -> 2021.7649 | J29: =LN(G29/I29) -> -0.010121064 | K29: =100 -> 100 | L29: =-1/Theta*(m_0-F29-Psi*G29) -> 1.9769681 | M29: =Mi*LN(G29/(I29)) -> -0.0010121064 | N29: =L29-M29 -> 1.9779802 | O29: =Ni*(H29-G29) -> -0.030470425 | P29: 0.018008217 | Q29: =$C$33*Q28+P29 -> 0.010823665 | R29: =EXP(Q29) -> 1.0108825
A30: Modulus (1+λ1) | B30: =IF(C26=0,ABS(1+B26),SQRT((1+B26)^2+C26^2)) -> 1.370219 | E30: 27 | F30: =F29+M29 -> 0.91718717 | G30: =G29+O29 -> 2001.3752 | H30: =Beta0_0 -Beta1*(L30-M30) -> 2001.6948 | I30: =ypot_0*R30 -> 1888.7348 | J30: =LN(G30/I30) -> 0.057927395 | K30: =100 -> 100 | L30: =-1/Theta*(m_0-F30-Psi*G30) -> 1.9718968 | M30: =Mi*LN(G30/(I30)) -> 0.0057927395 | N30: =L30-M30 -> 1.9661041 | O30: =Ni*(H30-G30) -> 0.031957123 | P30: -0.066981317 | Q30: =$C$33*Q29+P30 -> -0.057240018 | R30: =EXP(Q30) -> 0.94436738
A31: Modulus (1+λ2) | B31: =IF(B27=0,ABS(1+B27),SQRT((1+B27)^2+C27^2)) -> 1.370219 | E31: 28 | F31: =F30+M30 -> 0.92297991 | G31: =G30+O30 -> 2001.4072 | H31: =Beta0_0 -Beta1*(L31-M31) -> 2000.9067 | I31: =ypot_0*R31 -> 1907.3606 | J31: =LN(G31/I31) -> 0.0481301 | K31: =100 -> 100 | L31: =-1/Theta*(m_0-F31-Psi*G31) -> 1.986678 | M31: =Mi*LN(G31/(I31)) -> 0.00481301 | N31: =L31-M31 -> 1.981865 | O31: =Ni*(H31-G31) -> -0.050043192 | P31: 0.0040892599 | Q31: =$C$33*Q30+P31 -> -0.047426757 | R31: =EXP(Q31) -> 0.95368032
E32: 29 | F32: =F31+M31 -> 0.92779292 | G32: =G31+O31 -> 2001.3571 | H32: =Beta0_0 -Beta1*(L32-M32) -> 2000.7138 | I32: =ypot_0*R32 -> 1892.8077 | J32: =LN(G32/I32) -> 0.055764225 | K32: =100 -> 100 | L32: =-1/Theta*(m_0-F32-Psi*G32) -> 1.9912997 | M32: =Mi*LN(G32/(I32)) -> 0.0055764225 | N32: =L32-M32 -> 1.9857233 | O32: =Ni*(H32-G32) -> -0.064330315 | P32: -0.012401805 | Q32: =$C$33*Q31+P32 -> -0.055085886 | R32: =EXP(Q32) -> 0.94640386
B33: Rho_z | C33: 0.9 | E33: 30 | F33: =F32+M32 -> 0.93336934 | G33: =G32+O32 -> 2001.2928 | H33: =Beta0_0 -Beta1*(L33-M33) -> 2000.2815 | I33: =ypot_0*R33 -> 1968.535 | J33: =LN(G33/I33) -> 0.01650375 | K33: =100 -> 100 | L33: =-1/Theta*(m_0-F33-Psi*G33) -> 1.9960195 | M33: =Mi*LN(G33/(I33)) -> 0.001650375 | N33: =L33-M33 -> 1.9943691 | O33: =Ni*(H33-G33) -> -0.10112659 | P33: 0.033719742 | Q33: =$C$33*Q32+P33 -> -0.015857555 | R33: =EXP(Q33) -> 0.98426751
B34: Std Dev z | C34: 0.05 | E34: 31 | F34: =F33+M33 -> 0.93501972 | G34: =G33+O33 -> 2001.1917 | H34: =Beta0_0 -Beta1*(L34-M34) -> 2000.6367 | I34: =ypot_0*R34 -> 1962.7084 | J34: =LN(G34/I34) -> 0.019417501 | K34: =100 -> 100 | L34: =-1/Theta*(m_0-F34-Psi*G34) -> 1.9892076 | M34: =Mi*LN(G34/(I34)) -> 0.0019417501 | N34: =L34-M34 -> 1.9872659 | O34: =Ni*(H34-G34) -> -0.05549751 | P34: =NORMINV(RAND(), 0, $C$34) -> -0.0045500382 | Q34: =$C$33*Q33+P34 -> -0.018821838 | R34: =EXP(Q34) -> 0.98135419
E35: 32 | F35: =F34+M34 -> 0.93696147 | G35: =G34+O34 -> 2001.1362 | H35: =Beta0_0 -Beta1*(L35-M35) -> 2000.7879 | I35: =ypot_0*R35 -> 1936.2025 | J35: =LN(G35/I35) -> 0.032986543 | K35: =100 -> 100 | L35: =-1/Theta*(m_0-F35-Psi*G35) -> 1.9875414 | M35: =Mi*LN(G35/(I35)) -> 0.0032986543 | N35: =L35-M35 -> 1.9842427 | O35: =Ni*(H35-G35) -> -0.034831984 | P35: =NORMINV(RAND(), 0, $C$34) -> -0.015478958 | Q35: =$C$33*Q34+P35 -> -0.032418612 | R35: =EXP(Q35) -> 0.96810124
E36: 33 | F36: =F35+M35 -> 0.94026012 | G36: =G35+O35 -> 2001.1014 | H36: =Beta0_0 -Beta1*(L36-M36) -> 2000.3588 | I36: =ypot_0*R36 -> 2044.962 | J36: =LN(G36/I36) -> -0.02168148 | K36: =100 -> 100 | L36: =-1/Theta*(m_0-F36-Psi*G36) -> 1.9906555 | M36: =Mi*LN(G36/(I36)) -> -0.002168148 | N36: =L36-M36 -> 1.9928236 | O36: =Ni*(H36-G36) -> -0.074253348 | P36: =NORMINV(RAND(), 0, $C$34) -> 0.051408755 | Q36: =$C$33*Q35+P36 -> 0.022232005 | R36: =EXP(Q36) -> 1.022481
E37: 34 | F37: =F36+M36 -> 0.93809197 | G37: =G36+O36 -> 2001.0271 | H37: =Beta0_0 -Beta1*(L37-M37) -> 2000.9644 | I37: =ypot_0*R37 -> 2037.7336 | J37: =LN(G37/I37) -> -0.018177597 | K37: =100 -> 100 | L37: =-1/Theta*(m_0-F37-Psi*G37) -> 1.9788938 | M37: =Mi*LN(G37/(I37)) -> -0.0018177597 | N37: =L37-M37 -> 1.9807116 | O37: =Ni*(H37-G37) -> -0.0062679176 | P37: =NORMINV(RAND(), 0, $C$34) -> -0.0013177895 | Q37: =$C$33*Q36+P37 -> 0.018691015 | R37: =EXP(Q37) -> 1.0188668
E38: 35 | F38: =F37+M37 -> 0.93627421 | G38: =G37+O37 -> 2001.0208 | H38: =Beta0_0 -Beta1*(L38-M38) -> 2001.3935 | I38: =ypot_0*R38 -> 1951.6018 | J38: =LN(G38/I38) -> 0.025006984 | K38: =100 -> 100 | L38: =-1/Theta*(m_0-F38-Psi*G38) -> 1.9746315 | M38: =Mi*LN(G38/(I38)) -> 0.0025006984 | N38: =L38-M38 -> 1.9721308 | O38: =Ni*(H38-G38) -> 0.03726272 | P38: =NORMINV(RAND(), 0, $C$34) -> -0.041318612 | Q38: =$C$33*Q37+P38 -> -0.024496698 | R38: =EXP(Q38) -> 0.97580091
E39: 36 | F39: =F38+M38 -> 0.93877491 | G39: =G38+O38 -> 2001.0581 | H39: =Beta0_0 -Beta1*(L39-M39) -> 2001.0453 | I39: =ypot_0*R39 -> 1917.4965 | J39: =LN(G39/I39) -> 0.042655642 | K39: =100 -> 100 | L39: =-1/Theta*(m_0-F39-Psi*G39) -> 1.9833592 | M39: =Mi*LN(G39/(I39)) -> 0.0042655642 | N39: =L39-M39 -> 1.9790936 | O39: =Ni*(H39-G39) -> -0.0012775664 | P39: =NORMINV(RAND(), 0, $C$34) -> -0.020079707 | Q39: =$C$33*Q38+P39 -> -0.042126735 | R39: =EXP(Q39) -> 0.95874827
E40: 37 | F40: =F39+M39 -> 0.94304048 | G40: =G39+O39 -> 2001.0568 | H40: =Beta0_0 -Beta1*(L40-M40) -> 2000.7701 | I40: =ypot_0*R40 -> 1862.718 | J40: =LN(G40/I40) -> 0.071638764 | K40: =100 -> 100 | L40: =-1/Theta*(m_0-F40-Psi*G40) -> 1.9917626 | M40: =Mi*LN(G40/(I40)) -> 0.0071638764 | N40: =L40-M40 -> 1.9845987 | O40: =Ni*(H40-G40) -> -0.028675108 | P40: =NORMINV(RAND(), 0, $C$34) -> -0.033196434 | Q40: =$C$33*Q39+P40 -> -0.071110496 | R40: =EXP(Q40) -> 0.93135898
...

Sheet Money-Path
A1: ΔM_step | B1: 0.25
A2: n_raise | B2: 8 | E2: Time | F2: p | G2: y | H2: yd | I2: yn | J2: Gap | K2: m | L2: i | M2: ∆p | N2: Real i | O2: ∆y | P2: epsilon | Q2: z | R2: Z | BP2: ΔM_policy
A3: n_hold | B3: 4 | E3: 0 | F3: =(Theta*Beta0_0)/Beta1+m_0-(Psi+Theta/Beta1)*ypot_0 -> 1 | G3: =ypot_0 -> 2000 | H3: =Beta0_0 -Beta1*(L3-M3) -> 2000 | I3: =ypot_0*R3 -> 2000 | J3: =LN(G3/I3) -> 0 | K3: =100 -> 100 | L3: =-1/Theta*(m_0-F3-Psi*G3) -> 2 | M3: =Mi*J3 -> 0 | N3: =L3-M3 -> 2 | O3: =Ni*(H3-G3) -> 1.3642421e-13 | P3: 0 | Q3: 0 | R3: 1 | BP3: 0
A4: p: Price level | B4: ∆p: Inflation | E4: 1 | F4: =F3+M3 -> 1 | G4: =G3+O3 -> 2000 | H4: =Beta0_0 -Beta1*(L4-M4) -> 2100 | I4: =ypot_0*R4 -> 2000 | J4: =LN(G4/I4) -> 2.220446e-16 | K4: =K3+1 -> 101 | L4: =MAX(0, -1/$B$11*(K4-F4-$B$10*G4)) -> 0 | M4: =Mi*LN(G4/(I4)) -> 2.220446e-17 | N4: =L4-M4 -> -2.220446e-17 | O4: =Ni*(H4-G4) -> 10 | P4: 0 | Q4: =$C$33*Q3+P4 -> 0 | R4: =EXP(Q4) -> 1 | BP4: =IF(1<=$B$2, $B$1,IF(1<=$B$2+$B$3, 0,IF(1<=$B$2+$B$3+$B$5, $B$7, 0))) -> 0.25
A5: n_return | B5: 8 | E5: 2 | F5: =F4+M4 -> 1 | G5: =G4+O4 -> 2010 | H5: =Beta0_0 -Beta1*(L5-M5) -> 2100.1385 | I5: =ypot_0*R5 -> 1955.0693 | J5: =LN(G5/I5) -> 0.02770907 | K5: =K4+1 -> 102 | L5: =MAX(0, -1/$B$11*(K5-F5-$B$10*G5)) -> 0 | M5: =Mi*LN(G5/(I5)) -> 0.002770907 | N5: =L5-M5 -> -0.002770907 | O5: =Ni*(H5-G5) -> 9.0138545 | P5: -0.022721528 | Q5: =$C$33*Q4+P5 -> -0.022721528 | R5: =EXP(Q5) -> 0.97753466 | BP5: =IF(2<=$B$2, $B$1,IF(2<=$B$2+$B$3, 0,IF(2<=$B$2+$B$3+$B$5, $B$7, 0))) -> 0.25
A6: target_m0 | B6: 100 | E6: 3 | F6: =F5+M5 -> 1.0027709 | G6: =G5+O5 -> 2019.0139 | H6: =Beta0_0 -Beta1*(L6-M6) -> 2100.2414 | I6: =ypot_0*R6 -> 1923.8419 | J6: =LN(G6/I6) -> 0.048285028 | K6: =K5+1 -> 103 | L6: =MAX(0, -1/$B$11*(K6-F6-$B$10*G6)) -> 0 | M6: =Mi*LN(G6/(I6)) -> 0.0048285028 | N6: =L6-M6 -> -0.0048285028 | O6: =Ni*(H6-G6) -> 8.1227571 | P6: -0.018373631 | Q6: =$C$33*Q5+P6 -> -0.038823007 | R6: =EXP(Q6) -> 0.96192095 | BP6: =IF(3<=$B$2, $B$1,IF(3<=$B$2+$B$3, 0,IF(3<=$B$2+$B$3+$B$5, $B$7, 0))) -> 0.25
A7: return_step | B7: =- (INDEX(K:K, 4 + $B$2 + $B$3 - 1) - $B$6) / $B$5 -> -1.5 | E7: 4 | F7: =F6+M6 -> 1.0075994 | G7: =G6+O6 -> 2027.1366 | H7: =Beta0_0 -Beta1*(L7-M7) -> 2100.0678 | I7: =ypot_0*R7 -> 1999.8303 | J7: =LN(G7/I7) -> 0.013561949 | K7: =K6+1 -> 104 | L7: =MAX(0, -1/$B$11*(K7-F7-$B$10*G7)) -> 0 | M7: =Mi*LN(G7/(I7)) -> 0.0013561949 | N7: =L7-M7 -> -0.0013561949 | O7: =Ni*(H7-G7) -> 7.2931198 | P7: 0.034855837 | Q7: =$C$33*Q6+P7 -> -8.4868881e-05 | R7: =EXP(Q7) -> 0.99991513 | BP7: =IF(4<=$B$2, $B$1,IF(4<=$B$2+$B$3, 0,IF(4<=$B$2+$B$3+$B$5, $B$7, 0))) -> 0.25
E8: 5 | F8: =F7+M7 -> 1.0089556 | G8: =G7+O7 -> 2034.4297 | H8: =Beta0_0 -Beta1*(L8-M8) -> 2099.7856 | I8: =ypot_0*R8 -> 2123.5825 | J8: =LN(G8/I8) -> -0.042888966 | K8: =K7+1 -> 105 | L8: =MAX(0, -1/$B$11*(K8-F8-$B$10*G8)) -> 0 | M8: =Mi*LN(G8/(I8)) -> -0.0042888966 | N8: =L8-M8 -> 0.0042888966 | O8: =Ni*(H8-G8) -> 6.5355824 | P8: 0.060033716 | Q8: =$C$33*Q7+P8 -> 0.059957334 | R8: =EXP(Q8) -> 1.0617912 | BP8: =IF(5<=$B$2, $B$1,IF(5<=$B$2+$B$3, 0,IF(5<=$B$2+$B$3+$B$5, $B$7, 0))) -> 0.25
A9: Parameters | E9: 6 | F9: =F8+M8 -> 1.0046667 | G9: =G8+O8 -> 2040.9653 | H9: =Beta0_0 -Beta1*(L9-M9) -> 2099.4109 | I9: =ypot_0*R9 -> 2296.1688 | J9: =LN(G9/I9) -> -0.11781912 | K9: =K8+1 -> 106 | L9: =MAX(0, -1/$B$11*(K9-F9-$B$10*G9)) -> 0 | M9: =Mi*LN(G9/(I9)) -> -0.011781912 | N9: =L9-M9 -> 0.011781912 | O9: =Ni*(H9-G9) -> 5.8445591 | P9: 0.084133227 | Q9: =$C$33*Q8+P9 -> 0.13809483 | R9: =EXP(Q9) -> 1.1480844 | BP9: =IF(6<=$B$2, $B$1,IF(6<=$B$2+$B$3, 0,IF(6<=$B$2+$B$3+$B$5, $B$7, 0))) -> 0.25
A10: Psi | B10: 0.05 | E10: 7 | F10: =F9+M9 -> 0.9928848 | G10: =G9+O9 -> 2046.8099 | H10: =Beta0_0 -Beta1*(L10-M10) -> 2099.7144 | I10: =ypot_0*R10 -> 2167.1253 | J10: =LN(G10/I10) -> -0.057119107 | K10: =K9+1 -> 107 | L10: =MAX(0, -1/$B$11*(K10-F10-$B$10*G10)) -> 0 | M10: =Mi*LN(G10/(I10)) -> -0.0057119107 | N10: =L10-M10 -> 0.0057119107 | O10: =Ni*(H10-G10) -> 5.2904532 | P10: -0.044030997 | Q10: =$C$33*Q9+P10 -> 0.080254348 | R10: =EXP(Q10) -> 1.0835626 | BP10: =IF(7<=$B$2, $B$1,IF(7<=$B$2+$B$3, 0,IF(7<=$B$2+$B$3+$B$5, $B$7, 0))) -> 0.25
A11: Theta | B11: 0.5 | E11: 8 | F11: =F10+M10 -> 0.98717289 | G11: =G10+O10 -> 2052.1003 | H11: =Beta0_0 -Beta1*(L11-M11) -> 2099.5436 | I11: =ypot_0*R11 -> 2248.211 | J11: =LN(G11/I11) -> -0.091270967 | K11: =K10+1 -> 108 | L11: =MAX(0, -1/$B$11*(K11-F11-$B$10*G11)) -> 0 | M11: =Mi*LN(G11/(I11)) -> -0.0091270967 | N11: =L11-M11 -> 0.0091270967 | O11: =Ni*(H11-G11) -> 4.7443319 | P11: 0.044758691 | Q11: =$C$33*Q10+P11 -> 0.1169876 | R11: =EXP(Q11) -> 1.1241055 | BP11: =IF(8<=$B$2, $B$1,IF(8<=$B$2+$B$3, 0,IF(8<=$B$2+$B$3+$B$5, $B$7, 0))) -> 0.25
A12: Beta1 | B12: 50 | E12: 9 | F12: =F11+M11 -> 0.97804579 | G12: =G11+O11 -> 2056.8447 | H12: =Beta0_0 -Beta1*(L12-M12) -> 2099.5256 | I12: =ypot_0*R12 -> 2261.5438 | J12: =LN(G12/I12) -> -0.094874609 | K12: =K11+1 -> 109 | L12: =MAX(0, -1/$B$11*(K12-F12-$B$10*G12)) -> 0 | M12: =Mi*LN(G12/(I12)) -> -0.0094874609 | N12: =L12-M12 -> 0.0094874609 | O12: =Ni*(H12-G12) -> 4.2680969 | P12: 0.017611674 | Q12: =$C$33*Q11+P12 -> 0.12290052 | R12: =EXP(Q12) -> 1.1307719 | BP12: =IF(9<=$B$2, $B$1,IF(9<=$B$2+$B$3, 0,IF(9<=$B$2+$B$3+$B$5, $B$7, 0))) -> 0
A13: Mi | B13: 0.1 | E13: 10 | F13: =F12+M12 -> 0.96855833 | G13: =G12+O12 -> 2061.1128 | H13: =Beta0_0 -Beta1*(L13-M13) -> 2099.84 | I13: =ypot_0*R13 -> 2128.1319 | J13: =LN(G13/I13) -> -0.031998549 | K13: =K12+1 -> 110 | L13: =MAX(0, -1/$B$11*(K13-F13-$B$10*G13)) -> 0 | M13: =Mi*LN(G13/(I13)) -> -0.0031998549 | N13: =L13-M13 -> 0.0031998549 | O13: =Ni*(H13-G13) -> 3.8727252 | P13: -0.048513088 | Q13: =$C$33*Q12+P13 -> 0.062097378 | R13: =EXP(Q13) -> 1.064066 | BP13: =IF(10<=$B$2, $B$1,IF(10<=$B$2+$B$3, 0,IF(10<=$B$2+$B$3+$B$5, $B$7, 0))) -> 0
A14: Ni | B14: 0.1 | E14: 11 | F14: =F13+M13 -> 0.96535847 | G14: =G13+O13 -> 2064.9855 | H14: =Beta0_0 -Beta1*(L14-M14) -> 2099.7661 | I14: =ypot_0*R14 -> 2163.8752 | J14: =LN(G14/I14) -> -0.046777492 | K14: =K13+1 -> 111 | L14: =MAX(0, -1/$B$11*(K14-F14-$B$10*G14)) -> 0 | M14: =Mi*LN(G14/(I14)) -> -0.0046777492 | N14: =L14-M14 -> 0.0046777492 | O14: =Ni*(H14-G14) -> 3.4780632 | P14: 0.022865866 | Q14: =$C$33*Q13+P14 -> 0.078753506 | R14: =EXP(Q14) -> 1.0819376 | BP14: =IF(11<=$B$2, $B$1,IF(11<=$B$2+$B$3, 0,IF(11<=$B$2+$B$3+$B$5, $B$7, 0))) -> 0
E15: 12 | F15: =F14+M14 -> 0.96068072 | G15: =G14+O14 -> 2068.4635 | H15: =Beta0_0 -Beta1*(L15-M15) -> 2100.2429 | I15: =ypot_0*R15 -> 1970.3835 | J15: =LN(G15/I15) -> 0.048577908 | K15: =K14+1 -> 112 | L15: =MAX(0, -1/$B$11*(K15-F15-$B$10*G15)) -> 0 | M15: =Mi*LN(G15/(I15)) -> 0.0048577908 | N15: =L15-M15 -> -0.0048577908 | O15: =Ni*(H15-G15) -> 3.1779346 | P15: -0.085797162 | Q15: =$C$33*Q14+P15 -> -0.014919007 | R15: =EXP(Q15) -> 0.98519173 | BP15: =IF(12<=$B$2, $B$1,IF(12<=$B$2+$B$3, 0,IF(12<=$B$2+$B$3+$B$5, $B$7, 0))) -> 0
A16: Exogenous variables | B16: Initial value | C16: Final value | E16: 13 | F16: =F15+M15 -> 0.96553851 | G16: =G15+O15 -> 2071.6415 | H16: =Beta0_0 -Beta1*(L16-M16) -> 2100.3949 | I16: =ypot_0*R16 -> 1914.2996 | J16: =LN(G16/I16) -> 0.078989483 | K16: =K15+1 -> 113 | L16: =MAX(0, -1/$B$11*(K16-F16-$B$10*G16)) -> 0 | M16: =Mi*LN(G16/(I16)) -> 0.0078989483 | N16: =L16-M16 -> -0.0078989483 | O16: =Ni*(H16-G16) -> 2.8753469 | P16: -0.03036828 | Q16: =$C$33*Q15+P16 -> -0.043795386 | R16: =EXP(Q16) -> 0.95714978 | BP16: =IF(13<=$B$2, $B$1,IF(13<=$B$2+$B$3, 0,IF(13<=$B$2+$B$3+$B$5, $B$7, 0))) -> -1.5
A17: m: Money | B17: 100 | C17: 100 | E17: 14 | F17: =F16+M16 -> 0.97343746 | G17: =G16+O16 -> 2074.5168 | H17: =Beta0_0 -Beta1*(L17-M17) -> 2100.3655 | I17: =ypot_0*R17 -> 1928.266 | J17: =LN(G17/I17) -> 0.073107131 | K17: =K16+1 -> 114 | L17: =MAX(0, -1/$B$11*(K17-F17-$B$10*G17)) -> 0 | M17: =Mi*LN(G17/(I17)) -> 0.0073107131 | N17: =L17-M17 -> -0.0073107131 | O17: =Ni*(H17-G17) -> 2.5848711 | P17: 0.0028898073 | Q17: =$C$33*Q16+P17 -> -0.03652604 | R17: =EXP(Q17) -> 0.96413299 | BP17: =IF(14<=$B$2, $B$1,IF(14<=$B$2+$B$3, 0,IF(14<=$B$2+$B$3+$B$5, $B$7, 0))) -> -1.5
A18: Beta0: Government spending | B18: 2100 | C18: 2100 | E18: 15 | F18: =F17+M17 -> 0.98074818 | G18: =G17+O17 -> 2077.1017 | H18: =Beta0_0 -Beta1*(L18-M18) -> 2100.2354 | I18: =ypot_0*R18 -> 1981.5586 | J18: =LN(G18/I18) -> 0.047089815 | K18: =K17+1 -> 115 | L18: =MAX(0, -1/$B$11*(K18-F18-$B$10*G18)) -> 0 | M18: =Mi*LN(G18/(I18)) -> 0.0047089815 | N18: =L18-M18 -> -0.0047089815 | O18: =Ni*(H18-G18) -> 2.3133753 | P18: 0.023609947 | Q18: =$C$33*Q17+P18 -> -0.0092634891 | R18: =EXP(Q18) -> 0.99077928 | BP18: =IF(15<=$B$2, $B$1,IF(15<=$B$2+$B$3, 0,IF(15<=$B$2+$B$3+$B$5, $B$7, 0))) -> -1.5
A19: Ypot: Potential output | B19: 2000 | C19: 2000 | E19: 16 | F19: =F18+M18 -> 0.98545716 | G19: =G18+O18 -> 2079.4151 | H19: =Beta0_0 -Beta1*(L19-M19) -> 2100.0134 | I19: =ypot_0*R19 -> 2073.8458 | J19: =LN(G19/I19) -> 0.0026818826 | K19: =K18+1 -> 116 | L19: =MAX(0, -1/$B$11*(K19-F19-$B$10*G19)) -> 0 | M19: =Mi*LN(G19/(I19)) -> 0.00026818826 | N19: =L19-M19 -> -0.00026818826 | O19: =Ni*(H19-G19) -> 2.0598338 | P19: 0.044594715 | Q19: =$C$33*Q18+P19 -> 0.036257575 | R19: =EXP(Q19) -> 1.0369229 | BP19: =IF(16<=$B$2, $B$1,IF(16<=$B$2+$B$3, 0,IF(16<=$B$2+$B$3+$B$5, $B$7, 0))) -> -1.5
E20: 17 | F20: =F19+M19 -> 0.98572535 | G20: =G19+O19 -> 2081.4749 | H20: =Beta0_0 -Beta1*(L20-M20) -> 2099.4593 | I20: =ypot_0*R20 -> 2319.1784 | J20: =LN(G20/I20) -> -0.10813627 | K20: =K19+1 -> 117 | L20: =MAX(0, -1/$B$11*(K20-F20-$B$10*G20)) -> 0 | M20: =Mi*LN(G20/(I20)) -> -0.010813627 | N20: =L20-M20 -> 0.010813627 | O20: =Ni*(H20-G20) -> 1.7984414 | P20: 0.115434 | Q20: =$C$33*Q19+P20 -> 0.14806582 | R20: =EXP(Q20) -> 1.1595892 | BP20: =IF(17<=$B$2, $B$1,IF(17<=$B$2+$B$3, 0,IF(17<=$B$2+$B$3+$B$5, $B$7, 0))) -> -1.5
A21: Steady State | B21: Initial SS | C21: Final SS | E21: 18 | F21: =F20+M20 -> 0.97491172 | G21: =G20+O20 -> 2083.2733 | H21: =Beta0_0 -Beta1*(L21-M21) -> 2099.6238 | I21: =ypot_0*R21 -> 2246.0826 | J21: =LN(G21/I21) -> -0.07524723 | K21: =K20+1 -> 118 | L21: =MAX(0, -1/$B$11*(K21-F21-$B$10*G21)) -> 0 | M21: =Mi*LN(G21/(I21)) -> -0.007524723 | N21: =L21-M21 -> 0.007524723 | O21: =Ni*(H21-G21) -> 1.6350417 | P21: -0.017218807 | Q21: =$C$33*Q20+P21 -> 0.11604043 | R21: =EXP(Q21) -> 1.1230413 | BP21: =IF(18<=$B$2, $B$1,IF(18<=$B$2+$B$3, 0,IF(18<=$B$2+$B$3+$B$5, $B$7, 0))) -> -1.5
A22: Steady state for p | B22: =(Theta*Beta0_0)/Beta1+m_0-(Psi+Theta/Beta1)*ybar0 -> 1 | C22: =(Theta*Beta0_1)/Beta1+m_1-(Psi+Theta/Beta1)*ybar1 -> 1 | E22: 19 | F22: =F21+M21 -> 0.967387 | G22: =G21+O21 -> 2084.9084 | H22: =Beta0_0 -Beta1*(L22-M22) -> 2099.9821 | I22: =ypot_0*R22 -> 2092.3829 | J22: =LN(G22/I22) -> -0.0035786676 | K22: =K21+1 -> 119 | L22: =MAX(0, -1/$B$11*(K22-F22-$B$10*G22)) -> 0 | M22: =Mi*LN(G22/(I22)) -> -0.00035786676 | N22: =L22-M22 -> 0.00035786676 | O22: =Ni*(H22-G22) -> 1.5073718 | P22: -0.059279985 | Q22: =$C$33*Q21+P22 -> 0.045156403 | R22: =EXP(Q22) -> 1.0461915 | BP22: =IF(19<=$B$2, $B$1,IF(19<=$B$2+$B$3, 0,IF(19<=$B$2+$B$3+$B$5, $B$7, 0))) -> -1.5
A23: Steady state for y | B23: =ypot0 -> 2000 | C23: =ypot1 -> 2000 | E23: 20 | F23: =F22+M22 -> 0.96702913 | G23: =G22+O22 -> 2086.4158 | H23: =Beta0_0 -Beta1*(L23-M23) -> 2099.9779 | I23: =ypot_0*R23 -> 2095.6482 | J23: =LN(G23/I23) -> -0.0044152553 | K23: =K22+1 -> 120 | L23: =MAX(0, -1/$B$11*(K23-F23-$B$10*G23)) -> 0 | M23: =Mi*LN(G23/(I23)) -> -0.00044152553 | N23: =L23-M23 -> 0.00044152553 | O23: =Ni*(H23-G23) -> 1.3562164 | P23: 0.0060749586 | Q23: =$C$33*Q22+P23 -> 0.046715721 | R23: =EXP(Q23) -> 1.0478241 | BP23: =IF(20<=$B$2, $B$1,IF(20<=$B$2+$B$3, 0,IF(20<=$B$2+$B$3+$B$5, $B$7, 0))) -> -1.5
E24: 21 | F24: =F23+M23 -> 0.9665876 | G24: =G23+O23 -> 2087.772 | H24: =Beta0_0 -Beta1*(L24-M24) -> 2100.1829 | I24: =ypot_0*R24 -> 2012.7874 | J24: =LN(G24/I24) -> 0.036576922 | K24: =K23+1 -> 121 | L24: =MAX(0, -1/$B$11*(K24-F24-$B$10*G24)) -> 0 | M24: =Mi*LN(G24/(I24)) -> 0.0036576922 | N24: =L24-M24 -> -0.0036576922 | O24: =Ni*(H24-G24) -> 1.2410908 | P24: -0.035670794 | Q24: =$C$33*Q23+P24 -> 0.0063733546 | R24: =EXP(Q24) -> 1.0063937 | BP24: =IF(21<=$B$2, $B$1,IF(21<=$B$2+$B$3, 0,IF(21<=$B$2+$B$3+$B$5, $B$7, 0))) -> 0
A25: Eigenvalues | B25: Real | C25: Imaginary | E25: 22 | F25: =F24+M24 -> 0.9702453 | G25: =G24+O24 -> 2089.0131 | H25: =Beta0_0 -Beta1*(L25-M25) -> 2100.2695 | I25: =ypot_0*R25 -> 1979.3853 | J25: =LN(G25/I25) -> 0.053905401 | K25: =K24+1 -> 122 | L25: =MAX(0, -1/$B$11*(K25-F25-$B$10*G25)) -> 0 | M25: =Mi*LN(G25/(I25)) -> 0.0053905401 | N25: =L25-M25 -> -0.0053905401 | O25: =Ni*(H25-G25) -> 1.125646 | P25: -0.016096863 | Q25: =$C$33*Q24+P25 -> -0.010360843 | R25: =EXP(Q25) -> 0.98969265 | BP25: =IF(22<=$B$2, $B$1,IF(22<=$B$2+$B$3, 0,IF(22<=$B$2+$B$3+$B$5, $B$7, 0))) -> 0
A26: λ1 | B26: =IF((Ni*(Beta1*Mi-((Beta1*Psi)/Theta)-1))^2-4*(Ni*Beta1*Mi)/Theta>0,(Ni*(Beta1*Mi-((Beta1*Psi)/Theta)-1)+SQRT((Ni*(Beta1*Mi-((Beta1*Psi)/Theta)-1))^2-4*(Ni*Beta1*Mi)/Theta))/2,((Ni*(Beta1*Mi-((Beta1*Psi)/Theta)-1))/2)) -> -0.05 | C26: =IF((Ni*((Beta1*Mi-(Beta1*Psi)/Theta)-1)^2-4*(Ni*Beta1*Mi)/Theta)>0, 0, +SQRT(-(Ni*((Beta1*Mi-(Beta1*Psi)/Theta)-1)^2-4*(Ni*Beta1*Mi)/Theta))/2) -> 0.98742088 | E26: 23 | F26: =F25+M25 -> 0.97563584 | G26: =G25+O25 -> 2090.1387 | H26: =Beta0_0 -Beta1*(L26-M26) -> 2100.3884 | I26: =ypot_0*R26 -> 1933.9089 | J26: =LN(G26/I26) -> 0.077687163 | K26: =K25+1 -> 123 | L26: =MAX(0, -1/$B$11*(K26-F26-$B$10*G26)) -> 0 | M26: =Mi*LN(G26/(I26)) -> 0.0077687163 | N26: =L26-M26 -> -0.0077687163 | O26: =Ni*(H26-G26) -> 1.0249723 | P26: -0.02427915 | Q26: =$C$33*Q25+P26 -> -0.03360391 | R26: =EXP(Q26) -> 0.96695443 | BP26: =IF(23<=$B$2, $B$1,IF(23<=$B$2+$B$3, 0,IF(23<=$B$2+$B$3+$B$5, $B$7, 0))) -> 0
A27: λ2 | B27: =IF((Ni*(Beta1*Mi-((Beta1*Psi)/Theta)-1))^2-4*(Ni*Beta1*Mi)/Theta>0,(Ni*(Beta1*Mi-((Beta1*Psi)/Theta)-1)-SQRT((Ni*(Beta1*Mi-((Beta1*Psi)/Theta)-1))^2-4*(Ni*Beta1*Mi)/Theta))/2,((Ni*(Beta1*Mi-((Beta1*Psi)/Theta)-1))/2)) -> -0.05 | C27: =IF((Ni*((Beta1*Mi-(Beta1*Psi)/Theta)-1)^2-4*(Ni*Beta1*Mi)/Theta)>0, 0, -SQRT(-(Ni*((Beta1*Mi-(Beta1*Psi)/Theta)-1)^2-4*(Ni*Beta1*Mi)/Theta))/2) -> -0.98742088 | E27: 24 | F27: =F26+M26 -> 0.98340455 | G27: =G26+O26 -> 2091.1637 | H27: =Beta0_0 -Beta1*(L27-M27) -> 2100.291 | I27: =ypot_0*R27 -> 1972.9516 | J27: =LN(G27/I27) -> 0.058190022 | K27: =K26+1 -> 124 | L27: =MAX(0, -1/$B$11*(K27-F27-$B$10*G27)) -> 0 | M27: =Mi*LN(G27/(I27)) -> 0.0058190022 | N27: =L27-M27 -> -0.0058190022 | O27: =Ni*(H27-G27) -> 0.91272646 | P27: 0.016627014 | Q27: =$C$33*Q26+P27 -> -0.013616504 | R27: =EXP(Q27) -> 0.98647578 | BP27: =IF(24<=$B$2, $B$1,IF(24<=$B$2+$B$3, 0,IF(24<=$B$2+$B$3+$B$5, $B$7, 0))) -> 0
E28: 25 | F28: =F27+M27 -> 0.98922355 | G28: =G27+O27 -> 2092.0764 | H28: =Beta0_0 -Beta1*(L28-M28) -> 2100.265 | I28: =ypot_0*R28 -> 1984.0979 | J28: =LN(G28/I28) -> 0.052992726 | K28: =K27+1 -> 125 | L28: =MAX(0, -1/$B$11*(K28-F28-$B$10*G28)) -> 0 | M28: =Mi*LN(G28/(I28)) -> 0.0052992726 | N28: =L28-M28 -> -0.0052992726 | O28: =Ni*(H28-G28) -> 0.81885517 | P28: 0.0042720185 | Q28: =$C$33*Q27+P28 -> -0.0079828353 | R28: =EXP(Q28) -> 0.99204894 | BP28: =IF(25<=$B$2, $B$1,IF(25<=$B$2+$B$3, 0,IF(25<=$B$2+$B$3+$B$5, $B$7, 0))) -> 0
A29: Stability condition | E29: 26 | F29: =F28+M28 -> 0.99452283 | G29: =G28+O28 -> 2092.8953 | H29: =Beta0_0 -Beta1*(L29-M29) -> 2100.1729 | I29: =ypot_0*R29 -> 2021.7649 | J29: =LN(G29/I29) -> 0.034577557 | K29: =K28+1 -> 126 | L29: =MAX(0, -1/$B$11*(K29-F29-$B$10*G29)) -> 0 | M29: =Mi*LN(G29/(I29)) -> 0.0034577557 | N29: =L29-M29 -> -0.0034577557 | O29: =Ni*(H29-G29) -> 0.72776207 | P29: 0.018008217 | Q29: =$C$33*Q28+P29 -> 0.010823665 | R29: =EXP(Q29) -> 1.0108825 | BP29: =IF(26<=$B$2, $B$1,IF(26<=$B$2+$B$3, 0,IF(26<=$B$2+$B$3+$B$5, $B$7, 0))) -> 0
A30: Modulus (1+λ1) | B30: =IF(C26=0,ABS(1+B26),SQRT((1+B26)^2+C26^2)) -> 1.370219 | E30: 27 | F30: =F29+M29 -> 0.99798058 | G30: =G29+O29 -> 2093.623 | H30: =Beta0_0 -Beta1*(L30-M30) -> 2100.5149 | I30: =ypot_0*R30 -> 1888.7348 | J30: =LN(G30/I30) -> 0.10298891 | K30: =K29+1 -> 127 | L30: =MAX(0, -1/$B$11*(K30-F30-$B$10*G30)) -> 0 | M30: =Mi*LN(G30/(I30)) -> 0.010298891 | N30: =L30-M30 -> -0.010298891 | O30: =Ni*(H30-G30) -> 0.68919154 | P30: -0.066981317 | Q30: =$C$33*Q29+P30 -> -0.057240018 | R30: =EXP(Q30) -> 0.94436738 | BP30: =IF(27<=$B$2, $B$1,IF(27<=$B$2+$B$3, 0,IF(27<=$B$2+$B$3+$B$5, $B$7, 0))) -> 0
A31: Modulus (1+λ2) | B31: =IF(B27=0,ABS(1+B27),SQRT((1+B27)^2+C27^2)) -> 1.370219 | E31: 28 | F31: =F30+M30 -> 1.0082795 | G31: =G30+O30 -> 2094.3122 | H31: =Beta0_0 -Beta1*(L31-M31) -> 2100.4675 | I31: =ypot_0*R31 -> 1907.3606 | J31: =LN(G31/I31) -> 0.09350478 | K31: =K30+1 -> 128 | L31: =MAX(0, -1/$B$11*(K31-F31-$B$10*G31)) -> 0 | M31: =Mi*LN(G31/(I31)) -> 0.009350478 | N31: =L31-M31 -> -0.009350478 | O31: =Ni*(H31-G31) -> 0.61553032 | P31: 0.0040892599 | Q31: =$C$33*Q30+P31 -> -0.047426757 | R31: =EXP(Q31) -> 0.95368032 | BP31: =IF(28<=$B$2, $B$1,IF(28<=$B$2+$B$3, 0,IF(28<=$B$2+$B$3+$B$5, $B$7, 0))) -> 0
E32: 29 | F32: =F31+M31 -> 1.01763 | G32: =G31+O31 -> 2094.9278 | H32: =Beta0_0 -Beta1*(L32-M32) -> 2100.5073 | I32: =ypot_0*R32 -> 1892.8077 | J32: =LN(G32/I32) -> 0.10145777 | K32: =K31+1 -> 129 | L32: =MAX(0, -1/$B$11*(K32-F32-$B$10*G32)) -> 0 | M32: =Mi*LN(G32/(I32)) -> 0.010145777 | N32: =L32-M32 -> -0.010145777 | O32: =Ni*(H32-G32) -> 0.55795378 | P32: -0.012401805 | Q32: =$C$33*Q31+P32 -> -0.055085886 | R32: =EXP(Q32) -> 0.94640386 | BP32: =IF(29<=$B$2, $B$1,IF(29<=$B$2+$B$3, 0,IF(29<=$B$2+$B$3+$B$5, $B$7, 0))) -> 0
B33: Rho_z | C33: 0.9 | E33: 30 | F33: =F32+M32 -> 1.0277757 | G33: =G32+O32 -> 2095.4857 | H33: =Beta0_0 -Beta1*(L33-M33) -> 2100.3125 | I33: =ypot_0*R33 -> 1968.535 | J33: =LN(G33/I33) -> 0.062495741 | K33: =K32+1 -> 130 | L33: =MAX(0, -1/$B$11*(K33-F33-$B$10*G33)) -> 0 | M33: =Mi*LN(G33/(I33)) -> 0.0062495741 | N33: =L33-M33 -> -0.0062495741 | O33: =Ni*(H33-G33) -> 0.48267739 | P33: 0.033719742 | Q33: =$C$33*Q32+P33 -> -0.015857555 | R33: =EXP(Q33) -> 0.98426751 | BP33: =IF(30<=$B$2, $B$1,IF(30<=$B$2+$B$3, 0,IF(30<=$B$2+$B$3+$B$5, $B$7, 0))) -> 0
B34: Std Dev z | C34: 0.05 | E34: 31 | F34: =F33+M33 -> 1.0340253 | G34: =G33+O33 -> 2095.9684 | H34: =Beta0_0 -Beta1*(L34-M34) -> 2100.4839 | I34: =ypot_0*R34 -> 1902.6227 | J34: =LN(G34/I34) -> 0.096782371 | K34: =K33+1 -> 131 | L34: =MAX(0, -1/$B$11*(K34-F34-$B$10*G34)) -> 0 | M34: =Mi*LN(G34/(I34)) -> 0.0096782371 | N34: =L34-M34 -> -0.0096782371 | O34: =Ni*(H34-G34) -> 0.45155297 | P34: =NORMINV(RAND(), 0, $C$34) -> -0.035642071 | Q34: =$C$33*Q33+P34 -> -0.04991387 | R34: =EXP(Q34) -> 0.95131136
E35: 32 | F35: =F34+M34 -> 1.0437035 | G35: =G34+O34 -> 2096.4199 | H35: =Beta0_0 -Beta1*(L35-M35) -> 2100.4173 | I35: =ypot_0*R35 -> 1928.5737 | J35: =LN(G35/I35) -> 0.083450366 | K35: =K34-1 -> 130 | L35: =MAX(0, -1/$B$11*(K35-F35-$B$10*G35)) -> 0 | M35: =Mi*LN(G35/(I35)) -> 0.0083450366 | N35: =L35-M35 -> -0.0083450366 | O35: =Ni*(H35-G35) -> 0.39973167 | P35: =NORMINV(RAND(), 0, $C$34) -> 0.0085560338 | Q35: =$C$33*Q34+P35 -> -0.03636645 | R35: =EXP(Q35) -> 0.96428687
E36: 33 | F36: =F35+M35 -> 1.0520486 | G36: =G35+O35 -> 2096.8197 | H36: =Beta0_0 -Beta1*(L36-M36) -> 2100.1954 | I36: =ypot_0*R36 -> 2016.475 | J36: =LN(G36/I36) -> 0.039070834 | K36: =K35-1 -> 129 | L36: =MAX(0, -1/$B$11*(K36-F36-$B$10*G36)) -> 0 | M36: =Mi*LN(G36/(I36)) -> 0.0039070834 | N36: =L36-M36 -> -0.0039070834 | O36: =Ni*(H36-G36) -> 0.33756873 | P36: =NORMINV(RAND(), 0, $C$34) -> 0.040933543 | Q36: =$C$33*Q35+P36 -> 0.008203738 | R36: =EXP(Q36) -> 1.0082375
E37: 34 | F37: =F36+M36 -> 1.0559557 | G37: =G36+O36 -> 2097.1572 | H37: =Beta0_0 -Beta1*(L37-M37) -> 2100.1764 | I37: =ypot_0*R37 -> 2024.4547 | J37: =LN(G37/I37) -> 0.035282331 | K37: =K36-1 -> 128 | L37: =MAX(0, -1/$B$11*(K37-F37-$B$10*G37)) -> 0 | M37: =Mi*LN(G37/(I37)) -> 0.0035282331 | N37: =L37-M37 -> -0.0035282331 | O37: =Ni*(H37-G37) -> 0.30191761 | P37: =NORMINV(RAND(), 0, $C$34) -> 0.0047698545 | Q37: =$C$33*Q36+P37 -> 0.012153219 | R37: =EXP(Q37) -> 1.0122274
E38: 35 | F38: =F37+M37 -> 1.0594839 | G38: =G37+O37 -> 2097.4592 | H38: =Beta0_0 -Beta1*(L38-M38) -> 2099.9205 | I38: =ypot_0*R38 -> 2131.0943 | J38: =LN(G38/I38) -> -0.015908937 | K38: =K37-1 -> 127 | L38: =MAX(0, -1/$B$11*(K38-F38-$B$10*G38)) -> 0 | M38: =Mi*LN(G38/(I38)) -> -0.0015908937 | N38: =L38-M38 -> 0.0015908937 | O38: =Ni*(H38-G38) -> 0.24613021 | P38: =NORMINV(RAND(), 0, $C$34) -> 0.052550545 | Q38: =$C$33*Q37+P38 -> 0.063488442 | R38: =EXP(Q38) -> 1.0655472
E39: 36 | F39: =F38+M38 -> 1.057893 | G39: =G38+O38 -> 2097.7053 | H39: =Beta0_0 -Beta1*(L39-M39) -> 2100.0127 | I39: =ypot_0*R39 -> 2092.3977 | J39: =LN(G39/I39) -> 0.0025333891 | K39: =K38-1 -> 126 | L39: =MAX(0, -1/$B$11*(K39-F39-$B$10*G39)) -> 0 | M39: =Mi*LN(G39/(I39)) -> 0.00025333891 | N39: =L39-M39 -> -0.00025333891 | O39: =Ni*(H39-G39) -> 0.23073836 | P39: =NORMINV(RAND(), 0, $C$34) -> -0.011976142 | Q39: =$C$33*Q38+P39 -> 0.045163455 | R39: =EXP(Q39) -> 1.0461989
E40: 37 | F40: =F39+M39 -> 1.0581463 | G40: =G39+O39 -> 2097.936 | H40: =Beta0_0 -Beta1*(L40-M40) -> 2099.9325 | I40: =ypot_0*R40 -> 2126.4571 | J40: =LN(G40/I40) -> -0.013503262 | K40: =K39-1 -> 125 | L40: =MAX(0, -1/$B$11*(K40-F40-$B$10*G40)) -> 0 | M40: =Mi*LN(G40/(I40)) -> -0.0013503262 | N40: =L40-M40 -> 0.0013503262 | O40: =Ni*(H40-G40) -> 0.19964619 | P40: =NORMINV(RAND(), 0, $C$34) -> 0.020662987 | Q40: =$C$33*Q39+P40 -> 0.061310096 | R40: =EXP(Q40) -> 1.0632286
...

Sheet summary
A7: Range: t = 1…30
A9: Time | B9: Δp (inflation) | C9: GAP (output gap) | D9: Real i | E9: |Δp-π*| | F9: |GAP|
A10: ='Money-Path'!E4 -> 1 | B10: ='Money-Path'!M4 -> 2.220446e-17 | C10: ='Money-Path'!J4 -> 2.220446e-16 | D10: ='Money-Path'!N4 -> -2.220446e-17 | E10: =ABS(B10 - $B$1) -> 2.220446e-17 | F10: =ABS(C10) -> 2.220446e-16
A11: ='Money-Path'!E5 -> 2 | B11: ='Money-Path'!M5 -> 0.002770907 | C11: ='Money-Path'!J5 -> 0.02770907 | D11: ='Money-Path'!N5 -> -0.002770907 | E11: =ABS(B11 - $B$1) -> 0.002770907 | F11: =ABS(C11) -> 0.02770907
A12: ='Money-Path'!E6 -> 3 | B12: ='Money-Path'!M6 -> 0.0048285028 | C12: ='Money-Path'!J6 -> 0.048285028 | D12: ='Money-Path'!N6 -> -0.0048285028 | E12: =ABS(B12 - $B$1) -> 0.0048285028 | F12: =ABS(C12) -> 0.048285028
A13: ='Money-Path'!E7 -> 4 | B13: ='Money-Path'!M7 -> 0.0013561949 | C13: ='Money-Path'!J7 -> 0.013561949 | D13: ='Money-Path'!N7 -> -0.0013561949 | E13: =ABS(B13 - $B$1) -> 0.0013561949 | F13: =ABS(C13) -> 0.013561949
A14: ='Money-Path'!E8 -> 5 | B14: ='Money-Path'!M8 -> -0.0042888966 | C14: ='Money-Path'!J8 -> -0.042888966 | D14: ='Money-Path'!N8 -> 0.0042888966 | E14: =ABS(B14 - $B$1) -> 0.0042888966 | F14: =ABS(C14) -> 0.042888966
A15: ='Money-Path'!E9 -> 6 | B15: ='Money-Path'!M9 -> -0.011781912 | C15: ='Money-Path'!J9 -> -0.11781912 | D15: ='Money-Path'!N9 -> 0.011781912 | E15: =ABS(B15 - $B$1) -> 0.011781912 | F15: =ABS(C15) -> 0.11781912
A16: ='Money-Path'!E10 -> 7 | B16: ='Money-Path'!M10 -> -0.0057119107 | C16: ='Money-Path'!J10 -> -0.057119107 | D16: ='Money-Path'!N10 -> 0.0057119107 | E16: =ABS(B16 - $B$1) -> 0.0057119107 | F16: =ABS(C16) -> 0.057119107
A17: ='Money-Path'!E11 -> 8 | B17: ='Money-Path'!M11 -> -0.0091270967 | C17: ='Money-Path'!J11 -> -0.091270967 | D17: ='Money-Path'!N11 -> 0.0091270967 | E17: =ABS(B17 - $B$1) -> 0.0091270967 | F17: =ABS(C17) -> 0.091270967
A18: ='Money-Path'!E12 -> 9 | B18: ='Money-Path'!M12 -> -0.0094874609 | C18: ='Money-Path'!J12 -> -0.094874609 | D18: ='Money-Path'!N12 -> 0.0094874609 | E18: =ABS(B18 - $B$1) -> 0.0094874609 | F18: =ABS(C18) -> 0.094874609
A19: ='Money-Path'!E13 -> 10 | B19: ='Money-Path'!M13 -> -0.0031998549 | C19: ='Money-Path'!J13 -> -0.031998549 | D19: ='Money-Path'!N13 -> 0.0031998549 | E19: =ABS(B19 - $B$1) -> 0.0031998549 | F19: =ABS(C19) -> 0.031998549
A20: ='Money-Path'!E14 -> 11 | B20: ='Money-Path'!M14 -> -0.0046777492 | C20: ='Money-Path'!J14 -> -0.046777492 | D20: ='Money-Path'!N14 -> 0.0046777492 | E20: =ABS(B20 - $B$1) -> 0.0046777492 | F20: =ABS(C20) -> 0.046777492
A21: ='Money-Path'!E15 -> 12 | B21: ='Money-Path'!M15 -> 0.0048577908 | C21: ='Money-Path'!J15 -> 0.048577908 | D21: ='Money-Path'!N15 -> -0.0048577908 | E21: =ABS(B21 - $B$1) -> 0.0048577908 | F21: =ABS(C21) -> 0.048577908
... A39: ='Money-Path'!E33 -> 30 | B39: ='Money-Path'!M33 -> 0.0062495741 | C39: ='Money-Path'!J33 -> 0.062495741 | D39: ='Money-Path'!N33 -> -0.0062495741 | E39: =ABS(B39 - $B$1) -> 0.0062495741 | F39: =ABS(C39) -> 0.062495741
A42: std | B42: =STDEV(B10:B39) -> 0.0065317683 | C42: =STDEV(C10:C39) -> 0.065317683
A43: loss | B43: =0.75*B42^2+0.25*C42^2 -> 0.0010985979
A46: variance of real interest rates
A47: =_xlfn.VAR.P(D10:D39) -> 4.1241864e-05
